Workbook

Sheet Equalização
B1: LABORATORIO | C1: CLASSE | D1: FAMILIA | E1: MATERIAL | F1: DESCRIÇÃO MATERIAL | G1: Estado | H1: Unidade | I1: Nome da Unidade | J1: Nome Fornecedor | K1: Volume | L1: Baseline | M1: Preço medio realizado | N1: Preço Acordo Vigente | O1: Spend acordo | P1: Fornecedor Contrato vigente | Q1: Preço médio 4T25 e 3T25 | R1: Spend ano Atual Peers | S1: Spend mensal | T1: ∆R$ | U1: ∆% | V1: Preço médio 4T25 e 3T25 | W1: Spend ano consumo | X1: Spend mensal | Y1: ∆R$ | Z1: ∆% | AA1: Premissa deflatora | AB1: Preço projetado | AC1: Spend projetado ano | AD1: ∆R$ projetado compras | AE1: ∆% ano compras | AF1: ∆R$ projetado consumo | AG1: ∆% ano consumo | AH1: STATUS | AI1: cronograma | AJ1: Fornecedor_final | AK1: Preço unit | AL1: Spend Cotado FINAL | AM1: ∆R$ Cotado | AN1: ∆% Cotado | AO1: FIRSTLAB | AP1: MARCA | AQ1: BD MICRO. | AR1: BD COLETA | AS1: CRAL | AT1: BMX MICRO. | AU1: MARCA | AV1: SARSTEDT | AW1: MARCA | AX1: POLAR FIX | AY1: MARCA | AZ1: MAFRA | BA1: MARCA | BB1: TERA MEDICAL | BC1: MARCA | BD1: PLASTLABOR / LABORCLIN | BE1: MARCA | BF1: SENSORIAL | BG1: MARCA | BH1: SOL-MILLENIUM | BI1: NEW PROV | BJ1: MARCA | BK1: DNEDX(TESTE) | BL1: DIPROMED | BM1: MARCA | BN1: DK Diag. | BO1: DOBBER | BP1: MARCA | BQ1: ADVAGEN | BR1: MARCA | BS1: ONMNIA | BT1: BIO-RAD | BU1: INJEX | BV1: ABBOT TESTE RAPIDO | BW1: MEDLEVERSOHN | BX1: GLOBAL TESTES | BY1: MASTER HIGIMED | BZ1: MARCA | CA1: PROBAC | CB1: MARCA | CC1: LABTECH | CD1: MARCA | CE1: ADVAGEM | CF1: MARCA | CG1: AGAR LAB | CH1: MOBIUS | CI1: GREINER | CJ1: WERFEN | CK1: B | CL1: B | CM1: B | CN1: B | CO1: B | CP1: B | CQ1: B | CR1: B | CS1: B | CT1: B | CU1: B | CV1: B | CW1: B | CX1: B | CY1: B | CZ1: B | DA1: B | DB1: B | DC1: B | DD1: B | DE1: B | DF1: C | DG1: C | DH1: C | DI1: C | DJ1: C | DK1: C | DL1: C | DM1: C | DN1: C | DO1: C | DP1: C | DQ1: C | DR1: C | DS1: C | DT1: C | DU1: C | DV1: C | DW1: C | DX1: C | DY1: C | DZ1: C | EA1: C | EB1: C | EC1: C | ED1: C | EE1: C | EF1: C | EG1: C | EH1: C | EI1: C | EJ1: C | EK1: C | EL1: C | EM1: C | EN1: C | EO1: C | EP1: C | EQ1: C | ER1: C | ES1: C | ET1: C | EU1: C | EV1: C | EW1: C | EX1: C | EY1: C | EZ1: C | FA1: C | FB1: C | FC1: C | FD1: C | FE1: C | FF1: C | FG1: C | FH1: C | FI1: C | FJ1: C | FK1: C | FL1: C | FM1: C | FN1: JAN | FO1: FEV | FP1: MAR | FQ1: ABR | FR1: MAI | FS1: JUN | FT1: JUL | FU1: AGO | FV1: SET | FW1: OUT | FX1: NOV | FY1: DEZ | FZ1: TOTAL 2026 | GA1: CARRY-OVER 2027 | GB1: Inicio Captação | GC1: JAN | GD1: FEV | GE1: MAR | GF1: ABR | GG1: MAI | GH1: JUN | GI1: JUL | GJ1: AGO | GK1: SET | GL1: OUT | GM1: NOV | GN1: DEZ | GO1: TOTAL 2026 | GP1: CARRY-OVER 2027 | GQ1: FAROL | GR1: ∆R$ consumo | GS1: ∆% ano | GT1: INICIO CAPTAÇÃO | GU1: JAN | GV1: FEV | GW1: MAR | GX1: ABR | GY1: MAI | GZ1: JUN | HA1: JUL | HB1: AGO | HC1: SET | HD1: OUT | HE1: NOV | HF1: DEZ | HG1: TOTAL 2026 | HH1: CARRY-OVER 2027 | HI1: FAROL | HK1: SKU único (flag) | HL1: SKU único por status (flag) | HM1: Projeção captação | HN1: Quadrante MATRIZ 2x2
A2: =TRIM(E2) -> 209340 | B2: LABORATORIO | C2: PRÉ ANALITICO | D2: TUBO | E2: 209340 | F2: TUBO CONECTOR INJETORA | G2: SP | H2: 3069 | I2: NDI-CD LAPA | J2: BAYER S.A. | K2: 78687 | L2: =M2*K2 -> 1407014.1 | M2: 17.881151 | O2: =N2*K2 -> 0 | Q2: 18.128439 | R2: =IF($Q2="",0,$Q2*$K2) -> 1426472.5 | S2: =R2/12 -> 118872.7 | T2: =IF($Q2=0,0,$R2-$L2) -> 19458.363 | U2: =IFERROR(IF(OR(Q2="",Q2=0),"",T2/L2),"") -> 0.013829544 | V2: 18.084527 | W2: =IF($V2="",0,$V2*$K2) -> 1423017.2 | X2: =W2/12 -> 118584.76 | Y2: =IF($V2=0,0,$W2-$L2) -> 16003.063 | Z2: =IFERROR(IF(OR(V2="",V2=0),"",Y2/L2),"") -> 0.011373776 | AA2: 0.12 | AB2: =Q2-Q2*AA2 -> 15.953026 | AC2: =AB2*K2 -> 1255295.8 | AD2: =AC2-R2 -> -171176.69 | AE2: =IF(R2=0,"",AD2/R2) -> -0.12 | AF2: =AC2-W2 -> -167721.39 | AG2: =AF2/W2 -> -0.11786323 | AH2: NÃO INICIADO | AJ2: =IFERROR(INDEX($AO$1:$FM$1,MATCH($AK2,$AO2:$FM2,0)),"") | AK2: =MIN(AO2:FM2) -> 0 | AL2: =AK2*K2 -> 0 | AM2: =IF(OR(AK2="",AK2=0),0,AL2-$W2) -> 0 | AN2: =IF(AK2=0,"",AM2/$W2) | FN2: =$AD2*#REF! -> #REF! | FO2: =$AD2*#REF! -> #REF! | FP2: =$AD2*#REF! -> #REF! | FQ2: =$AD2*#REF! -> #REF! | FR2: =$AD2*#REF! -> #REF! | FS2: =$AD2*#REF! -> #REF! | FT2: =$AD2*#REF! -> #REF! | FU2: =$AD2*#REF! -> #REF! | ... FY2: =$AD2*#REF! -> #REF! | FZ2: =SUM(FN2:FY2) -> #REF! | GA2: =AD2-FZ2 -> #REF! | GC2: =IF($GB2="jan",$AM2/12,0) -> 0 | GD2: =IF(GC2<>0,GC2,IF($GB2="fev",$AM2/12,0)) -> 0 | GE2: =IF(GD2<>0,GD2,IF($GB2="mar",$AM2/12,0)) -> 0 | GF2: =IF(GE2<>0,GE2,IF($GB2="abr",$AM2/12,0)) -> 0 | GG2: =IF(GF2<>0,GF2,IF($GB2="mai",$AM2/12,0)) -> 0 | GH2: =IF(GG2<>0,GG2,IF($GB2="jun",$AM2/12,0)) -> 0 | GI2: =IF(GH2<>0,GH2,IF($GB2="jul",$AM2/12,0)) -> 0 | GJ2: =IF(GI2<>0,GI2,IF($GB2="ago",$AM2/12,0)) -> 0 | GK2: =IF(GJ2<>0,GJ2,IF($GB2="set",$AM2/12,0)) -> 0 | GL2: =IF(GK2<>0,GK2,IF($GB2="out",$AM2/12,0)) -> 0 | GM2: =IF(GL2<>0,GL2,IF($GB2="nov",$AM2/12,0)) -> 0 | GN2: =IF(GM2<>0,GM2,IF($GB2="dez",$AM2/12,0)) -> 0 | GO2: =SUM(GC2:GN2) -> 0 | GP2: =IF(GB2="","",IF(AM2=0,0,AM2-GO2)) | GQ2: =IF(GO2=0,"",IF(GO2=FZ2,0,IF(GO2<FZ2,1,2))) | GR2: =IF(OR(AK2="",AK2=0),0,AL2-$W2) -> 0 | GS2: =IF(AK2=0,"",GR2/$W2) | GT2: =GB2 | GU2: =IF($GT2="jan",$GR2/12,0) -> 0 | GV2: =IF(GU2<>0,GU2,IF($GT2="fev",$GR2/12,0)) -> 0 | GW2: =IF(GV2<>0,GV2,IF($GT2="mar",$GR2/12,0)) -> 0 | GX2: =IF(GW2<>0,GW2,IF($GT2="abr",$GR2/12,0)) -> 0 | GY2: =IF(GX2<>0,GX2,IF($GT2="mai",$GR2/12,0)) -> 0 | GZ2: =IF(GY2<>0,GY2,IF($GT2="jun",$GR2/12,0)) -> 0 | HA2: =IF(GZ2<>0,GZ2,IF($GT2="jul",$GR2/12,0)) -> 0 | HB2: =IF(HA2<>0,HA2,IF($GT2="ago",$GR2/12,0)) -> 0 | HC2: =IF(HB2<>0,HB2,IF($GT2="set",$GR2/12,0)) -> 0 | HD2: =IF(HC2<>0,HC2,IF($GT2="out",$GR2/12,0)) -> 0 | HE2: =IF(HD2<>0,HD2,IF($GT2="nov",$GR2/12,0)) -> 0 | HF2: =IF(HE2<>0,HE2,IF($GT2="dez",$GR2/12,0)) -> 0 | HG2: =SUM(GU2:HF2) -> 0 | HH2: =IF(GT2=0,"",IF(GR2=0,0,GR2-HG2)) | HI2: =IF(HG2=0,"",IF(HG2=FZ2,0,IF(HG2<FZ2,1,2))) | HK2: 1 | HL2: 1 | HM2: =IF($GB2<>"",$GB2,IFERROR(T(INDEX('MATRIZ 2X2'!$J$20:$J$367,MATCH(UPPER(TRIM(SUBSTITUTE(IF(ISNUMBER(VALUE(LEFT(TRIM(J2),6))),MID(TRIM(J2),FIND(" ",TRIM(J2))+1,300),TRIM(J2)),".",""))),'MATRIZ 2X2'!$P$20:$P$367,0))),"")) | HN2: =IFERROR(INDEX('MATRIZ 2X2'!$G$20:$G$367,MATCH(UPPER(TRIM(SUBSTITUTE(IF(ISNUMBER(VALUE(LEFT(TRIM(J2),6))),MID(TRIM(J2),FIND(" ",TRIM(J2))+1,300),TRIM(J2)),".",""))),'MATRIZ 2X2'!$P$20:$P$367,0)),"")
A3: =TRIM(E3) -> 225698 | B3: LABORATORIO | C3: PRÉ ANALITICO | D3: SERINGA | E3: 225698 | F3: MS LUER ADAPTER 367290 BD REA SOL | G3: SP | H3: 3069 | I3: NDI-CD LAPA | J3: BECTON DICKINSON IND CIRURG LTDA | K3: 999100 | L3: =M3*K3 -> 1167946.7 | M3: 1.1689988 | N3: 1.17 | O3: =N3*K3 -> 1168947 | P3: BECTON DICKINSON INDUSTRIAS CIRURGI | Q3: 1.169 | R3: =IF($Q3="",0,$Q3*$K3) -> 1167947.9 | S3: =R3/12 -> 97328.992 | T3: =IF($Q3=0,0,$R3-$L3) -> 1.19 | U3: =IFERROR(IF(OR(Q3="",Q3=0),"",T3/L3),"") -> 1.0188821e-06 | V3: 1.1689826 | W3: =IF($V3="",0,$V3*$K3) -> 1167930.5 | X3: =W3/12 -> 97327.539 | Y3: =IF($V3=0,0,$W3-$L3) -> -16.24267 | Z3: =IFERROR(IF(OR(V3="",V3=0),"",Y3/L3),"") -> -1.390703e-05 | AA3: 0.12 | AB3: =Q3-Q3*AA3 -> 1.02872 | AC3: =AB3*K3 -> 1027794.2 | AD3: =AC3-R3 -> -140153.75 | AE3: =IF(R3=0,"",AD3/R3) -> -0.12 | AF3: =AC3-W3 -> -140136.32 | AG3: =AF3/W3 -> -0.11998686 | AH3: FINALIZADO | AJ3: =IFERROR(INDEX($AO$1:$FM$1,MATCH($AK3,$AO3:$FM3,0)),"") -> BD COLETA | AK3: =MIN(AO3:FM3) -> 1.169 | AL3: =AK3*K3 -> 1167947.9 | AM3: =IF(OR(AK3="",AK3=0),0,AL3-$W3) -> 17.43267 | AN3: =IF(AK3=0,"",AM3/$W3) -> 1.492612e-05 | AR3: 1.169 | FN3: =$AD3*#REF! -> #REF! | FO3: =$AD3*#REF! -> #REF! | FP3: =$AD3*#REF! -> #REF! | FQ3: =$AD3*#REF! -> #REF! | FR3: =$AD3*#REF! -> #REF! | FS3: =$AD3*#REF! -> #REF! | FT3: =$AD3*#REF! -> #REF! | FU3: =$AD3*#REF! -> #REF! | ... FY3: =$AD3*#REF! -> #REF! | FZ3: =SUM(FN3:FY3) -> #REF! | GA3: =AD3-FZ3 -> #REF! | GB3: JUN | GC3: =IF($GB3="jan",$AM3/12,0) -> 0 | GD3: =IF(GC3<>0,GC3,IF($GB3="fev",$AM3/12,0)) -> 0 | GE3: =IF(GD3<>0,GD3,IF($GB3="mar",$AM3/12,0)) -> 0 | GF3: =IF(GE3<>0,GE3,IF($GB3="abr",$AM3/12,0)) -> 0 | GG3: =IF(GF3<>0,GF3,IF($GB3="mai",$AM3/12,0)) -> 0 | GH3: =IF(GG3<>0,GG3,IF($GB3="jun",$AM3/12,0)) -> 1.4527225 | GI3: =IF(GH3<>0,GH3,IF($GB3="jul",$AM3/12,0)) -> 1.4527225 | GJ3: =IF(GI3<>0,GI3,IF($GB3="ago",$AM3/12,0)) -> 1.4527225 | GK3: =IF(GJ3<>0,GJ3,IF($GB3="set",$AM3/12,0)) -> 1.4527225 | GL3: =IF(GK3<>0,GK3,IF($GB3="out",$AM3/12,0)) -> 1.4527225 | GM3: =IF(GL3<>0,GL3,IF($GB3="nov",$AM3/12,0)) -> 1.4527225 | GN3: =IF(GM3<>0,GM3,IF($GB3="dez",$AM3/12,0)) -> 1.4527225 | GO3: =SUM(GC3:GN3) -> 10.169058 | GP3: =IF(GB3="","",IF(AM3=0,0,AM3-GO3)) -> 7.2636127 | GQ3: =IF(GO3=0,"",IF(GO3=FZ3,0,IF(GO3<FZ3,1,2))) -> #REF! | GR3: =IF(OR(AK3="",AK3=0),0,AL3-$W3) -> 17.43267 | GS3: =IF(AK3=0,"",GR3/$W3) -> 1.492612e-05 | GT3: =GB3 -> JUN | GU3: =IF($GT3="jan",$GR3/12,0) -> 0 | GV3: =IF(GU3<>0,GU3,IF($GT3="fev",$GR3/12,0)) -> 0 | GW3: =IF(GV3<>0,GV3,IF($GT3="mar",$GR3/12,0)) -> 0 | GX3: =IF(GW3<>0,GW3,IF($GT3="abr",$GR3/12,0)) -> 0 | GY3: =IF(GX3<>0,GX3,IF($GT3="mai",$GR3/12,0)) -> 0 | GZ3: =IF(GY3<>0,GY3,IF($GT3="jun",$GR3/12,0)) -> 1.4527225 | HA3: =IF(GZ3<>0,GZ3,IF($GT3="jul",$GR3/12,0)) -> 1.4527225 | HB3: =IF(HA3<>0,HA3,IF($GT3="ago",$GR3/12,0)) -> 1.4527225 | HC3: =IF(HB3<>0,HB3,IF($GT3="set",$GR3/12,0)) -> 1.4527225 | HD3: =IF(HC3<>0,HC3,IF($GT3="out",$GR3/12,0)) -> 1.4527225 | HE3: =IF(HD3<>0,HD3,IF($GT3="nov",$GR3/12,0)) -> 1.4527225 | HF3: =IF(HE3<>0,HE3,IF($GT3="dez",$GR3/12,0)) -> 1.4527225 | HG3: =SUM(GU3:HF3) -> 10.169058 | HH3: =IF(GT3=0,"",IF(GR3=0,0,GR3-HG3)) -> 7.2636127 | HI3: =IF(HG3=0,"",IF(HG3=FZ3,0,IF(HG3<FZ3,1,2))) -> #REF! | HK3: 1 | HL3: 1 | HM3: =IF($GB3<>"",$GB3,IFERROR(T(INDEX('MATRIZ 2X2'!$J$20:$J$367,MATCH(UPPER(TRIM(SUBSTITUTE(IF(ISNUMBER(VALUE(LEFT(TRIM(J3),6))),MID(TRIM(J3),FIND(" ",TRIM(J3))+1,300),TRIM(J3)),".",""))),'MATRIZ 2X2'!$P$20:$P$367,0))),"")) -> JUN | HN3: =IFERROR(INDEX('MATRIZ 2X2'!$G$20:$G$367,MATCH(UPPER(TRIM(SUBSTITUTE(IF(ISNUMBER(VALUE(LEFT(TRIM(J3),6))),MID(TRIM(J3),FIND(" ",TRIM(J3))+1,300),TRIM(J3)),".",""))),'MATRIZ 2X2'!$P$20:$P$367,0)),"")
A4: =TRIM(E4) -> 212235 | B4: LABORATORIO | C4: PRÉ ANALITICO | D4: TUBO | E4: 212235 | F4: VAC GEL SST 5ML 360060 TB 13X100MM | G4: SP | H4: 3069 | I4: NDI-CD LAPA | J4: BECTON DICKINSON IND CIRURG LTDA | K4: 1829500 | L4: =M4*K4 -> 1079394.7 | M4: 0.58999439 | N4: 0.64 | O4: =N4*K4 -> 1170880 | P4: BECTON DICKINSON INDUSTRIAS CIRURGI | Q4: 0.62803448 | R4: =IF($Q4="",0,$Q4*$K4) -> 1148989.1 | S4: =R4/12 -> 95749.09 | T4: =IF($Q4=0,0,$R4-$L4) -> 69594.352 | U4: =IFERROR(IF(OR(Q4="",Q4=0),"",T4/L4),"") -> 0.064475349 | V4: 0.63755821 | W4: =IF($V4="",0,$V4*$K4) -> 1166412.7 | X4: =W4/12 -> 97201.062 | Y4: =IF($V4=0,0,$W4-$L4) -> 87018.012 | Z4: =IFERROR(IF(OR(V4="",V4=0),"",Y4/L4),"") -> 0.080617415 | AA4: 0.12 | AB4: =Q4-Q4*AA4 -> 0.55267034 | AC4: =AB4*K4 -> 1011110.4 | AD4: =AC4-R4 -> -137878.69 | AE4: =IF(R4=0,"",AD4/R4) -> -0.12 | AF4: =AC4-W4 -> -155302.35 | AG4: =AF4/W4 -> -0.13314528 | AH4: FINALIZADO | AJ4: =IFERROR(INDEX($AO$1:$FM$1,MATCH($AK4,$AO4:$FM4,0)),"") -> BD COLETA | AK4: =MIN(AO4:FM4) -> 0.64 | AL4: =AK4*K4 -> 1170880 | AM4: =IF(OR(AK4="",AK4=0),0,AL4-$W4) -> 4467.2575 | AN4: =IF(AK4=0,"",AM4/$W4) -> 0.0038299115 | AR4: 0.64 | FN4: =$AD4*#REF! -> #REF! | FO4: =$AD4*#REF! -> #REF! | FP4: =$AD4*#REF! -> #REF! | FQ4: =$AD4*#REF! -> #REF! | FR4: =$AD4*#REF! -> #REF! | FS4: =$AD4*#REF! -> #REF! | FT4: =$AD4*#REF! -> #REF! | FU4: =$AD4*#REF! -> #REF! | ... FY4: =$AD4*#REF! -> #REF! | FZ4: =SUM(FN4:FY4) -> #REF! | GA4: =AD4-FZ4 -> #REF! | GB4: JUN | GC4: =IF($GB4="jan",$AM4/12,0) -> 0 | GD4: =IF(GC4<>0,GC4,IF($GB4="fev",$AM4/12,0)) -> 0 | GE4: =IF(GD4<>0,GD4,IF($GB4="mar",$AM4/12,0)) -> 0 | GF4: =IF(GE4<>0,GE4,IF($GB4="abr",$AM4/12,0)) -> 0 | GG4: =IF(GF4<>0,GF4,IF($GB4="mai",$AM4/12,0)) -> 0 | GH4: =IF(GG4<>0,GG4,IF($GB4="jun",$AM4/12,0)) -> 372.27146 | GI4: =IF(GH4<>0,GH4,IF($GB4="jul",$AM4/12,0)) -> 372.27146 | GJ4: =IF(GI4<>0,GI4,IF($GB4="ago",$AM4/12,0)) -> 372.27146 | GK4: =IF(GJ4<>0,GJ4,IF($GB4="set",$AM4/12,0)) -> 372.27146 | GL4: =IF(GK4<>0,GK4,IF($GB4="out",$AM4/12,0)) -> 372.27146 | GM4: =IF(GL4<>0,GL4,IF($GB4="nov",$AM4/12,0)) -> 372.27146 | GN4: =IF(GM4<>0,GM4,IF($GB4="dez",$AM4/12,0)) -> 372.27146 | GO4: =SUM(GC4:GN4) -> 2605.9002 | GP4: =IF(GB4="","",IF(AM4=0,0,AM4-GO4)) -> 1861.3573 | GQ4: =IF(GO4=0,"",IF(GO4=FZ4,0,IF(GO4<FZ4,1,2))) -> #REF! | GR4: =IF(OR(AK4="",AK4=0),0,AL4-$W4) -> 4467.2575 | GS4: =IF(AK4=0,"",GR4/$W4) -> 0.0038299115 | GT4: =GB4 -> JUN | GU4: =IF($GT4="jan",$GR4/12,0) -> 0 | GV4: =IF(GU4<>0,GU4,IF($GT4="fev",$GR4/12,0)) -> 0 | GW4: =IF(GV4<>0,GV4,IF($GT4="mar",$GR4/12,0)) -> 0 | GX4: =IF(GW4<>0,GW4,IF($GT4="abr",$GR4/12,0)) -> 0 | GY4: =IF(GX4<>0,GX4,IF($GT4="mai",$GR4/12,0)) -> 0 | GZ4: =IF(GY4<>0,GY4,IF($GT4="jun",$GR4/12,0)) -> 372.27146 | HA4: =IF(GZ4<>0,GZ4,IF($GT4="jul",$GR4/12,0)) -> 372.27146 | HB4: =IF(HA4<>0,HA4,IF($GT4="ago",$GR4/12,0)) -> 372.27146 | HC4: =IF(HB4<>0,HB4,IF($GT4="set",$GR4/12,0)) -> 372.27146 | HD4: =IF(HC4<>0,HC4,IF($GT4="out",$GR4/12,0)) -> 372.27146 | HE4: =IF(HD4<>0,HD4,IF($GT4="nov",$GR4/12,0)) -> 372.27146 | HF4: =IF(HE4<>0,HE4,IF($GT4="dez",$GR4/12,0)) -> 372.27146 | HG4: =SUM(GU4:HF4) -> 2605.9002 | HH4: =IF(GT4=0,"",IF(GR4=0,0,GR4-HG4)) -> 1861.3573 | HI4: =IF(HG4=0,"",IF(HG4=FZ4,0,IF(HG4<FZ4,1,2))) -> #REF! | HK4: 1 | HL4: 1 | HM4: =IF($GB4<>"",$GB4,IFERROR(T(INDEX('MATRIZ 2X2'!$J$20:$J$367,MATCH(UPPER(TRIM(SUBSTITUTE(IF(ISNUMBER(VALUE(LEFT(TRIM(J4),6))),MID(TRIM(J4),FIND(" ",TRIM(J4))+1,300),TRIM(J4)),".",""))),'MATRIZ 2X2'!$P$20:$P$367,0))),"")) -> JUN | HN4: =IFERROR(INDEX('MATRIZ 2X2'!$G$20:$G$367,MATCH(UPPER(TRIM(SUBSTITUTE(IF(ISNUMBER(VALUE(LEFT(TRIM(J4),6))),MID(TRIM(J4),FIND(" ",TRIM(J4))+1,300),TRIM(J4)),".",""))),'MATRIZ 2X2'!$P$20:$P$367,0)),"")
A5: =TRIM(E5) -> 150420 | B5: LABORATORIO | C5: PRÉ ANALITICO | D5: AGULHA | E5: 150420 | F5: AGULHA MULTI COL SANG DISPSEG 21G 368607 | G5: SP | H5: 3069 | I5: NDI-CD LAPA | J5: BECTON DICKINSON IND CIRURG LTDA | K5: 1578672 | L5: =M5*K5 -> 1057735.6 | M5: 0.67001608 | N5: 0.74 | O5: =N5*K5 -> 1168217.3 | P5: BECTON DICKINSON INDUSTRIAS CIRURGI | Q5: 0.77025788 | R5: =IF($Q5="",0,$Q5*$K5) -> 1215984.6 | S5: =R5/12 -> 101332.05 | T5: =IF($Q5=0,0,$R5-$L5) -> 158248.92 | U5: =IFERROR(IF(OR(Q5="",Q5=0),"",T5/L5),"") -> 0.14961104 | V5: 0.79462732 | W5: =IF($V5="",0,$V5*$K5) -> 1254455.9 | X5: =W5/12 -> 104537.99 | Y5: =IF($V5=0,0,$W5-$L5) -> 196720.28 | Z5: =IFERROR(IF(OR(V5="",V5=0),"",Y5/L5),"") -> 0.18598246 | AA5: 0.12 | AB5: =Q5-Q5*AA5 -> 0.67782694 | AC5: =AB5*K5 -> 1070066.4 | AD5: =AC5-R5 -> -145918.15 | AE5: =IF(R5=0,"",AD5/R5) -> -0.12 | AF5: =AC5-W5 -> -184389.5 | AG5: =AF5/W5 -> -0.14698763 | AH5: FINALIZADO | AJ5: =IFERROR(INDEX($AO$1:$FM$1,MATCH($AK5,$AO5:$FM5,0)),"") -> BD COLETA | AK5: =MIN(AO5:FM5) -> 0.74 | AL5: =AK5*K5 -> 1168217.3 | AM5: =IF(OR(AK5="",AK5=0),0,AL5-$W5) -> -86238.627 | AN5: =IF(AK5=0,"",AM5/$W5) -> -0.068745842 | AR5: 0.74 | BY5: 1.1544 | BZ5: LABOR IMPORT | FN5: =$AD5*#REF! -> #REF! | FO5: =$AD5*#REF! -> #REF! | FP5: =$AD5*#REF! -> #REF! | FQ5: =$AD5*#REF! -> #REF! | FR5: =$AD5*#REF! -> #REF! | FS5: =$AD5*#REF! -> #REF! | FT5: =$AD5*#REF! -> #REF! | FU5: =$AD5*#REF! -> #REF! | ... FY5: =$AD5*#REF! -> #REF! | FZ5: =SUM(FN5:FY5) -> #REF! | GA5: =AD5-FZ5 -> #REF! | GB5: JUN | GC5: =IF($GB5="jan",$AM5/12,0) -> 0 | GD5: =IF(GC5<>0,GC5,IF($GB5="fev",$AM5/12,0)) -> 0 | GE5: =IF(GD5<>0,GD5,IF($GB5="mar",$AM5/12,0)) -> 0 | GF5: =IF(GE5<>0,GE5,IF($GB5="abr",$AM5/12,0)) -> 0 | GG5: =IF(GF5<>0,GF5,IF($GB5="mai",$AM5/12,0)) -> 0 | GH5: =IF(GG5<>0,GG5,IF($GB5="jun",$AM5/12,0)) -> -7186.5523 | GI5: =IF(GH5<>0,GH5,IF($GB5="jul",$AM5/12,0)) -> -7186.5523 | GJ5: =IF(GI5<>0,GI5,IF($GB5="ago",$AM5/12,0)) -> -7186.5523 | GK5: =IF(GJ5<>0,GJ5,IF($GB5="set",$AM5/12,0)) -> -7186.5523 | GL5: =IF(GK5<>0,GK5,IF($GB5="out",$AM5/12,0)) -> -7186.5523 | GM5: =IF(GL5<>0,GL5,IF($GB5="nov",$AM5/12,0)) -> -7186.5523 | GN5: =IF(GM5<>0,GM5,IF($GB5="dez",$AM5/12,0)) -> -7186.5523 | GO5: =SUM(GC5:GN5) -> -50305.866 | GP5: =IF(GB5="","",IF(AM5=0,0,AM5-GO5)) -> -35932.761 | GQ5: =IF(GO5=0,"",IF(GO5=FZ5,0,IF(GO5<FZ5,1,2))) -> #REF! | GR5: =IF(OR(AK5="",AK5=0),0,AL5-$W5) -> -86238.627 | GS5: =IF(AK5=0,"",GR5/$W5) -> -0.068745842 | GT5: =GB5 -> JUN | GU5: =IF($GT5="jan",$GR5/12,0) -> 0 | GV5: =IF(GU5<>0,GU5,IF($GT5="fev",$GR5/12,0)) -> 0 | GW5: =IF(GV5<>0,GV5,IF($GT5="mar",$GR5/12,0)) -> 0 | GX5: =IF(GW5<>0,GW5,IF($GT5="abr",$GR5/12,0)) -> 0 | GY5: =IF(GX5<>0,GX5,IF($GT5="mai",$GR5/12,0)) -> 0 | GZ5: =IF(GY5<>0,GY5,IF($GT5="jun",$GR5/12,0)) -> -7186.5523 | HA5: =IF(GZ5<>0,GZ5,IF($GT5="jul",$GR5/12,0)) -> -7186.5523 | HB5: =IF(HA5<>0,HA5,IF($GT5="ago",$GR5/12,0)) -> -7186.5523 | HC5: =IF(HB5<>0,HB5,IF($GT5="set",$GR5/12,0)) -> -7186.5523 | HD5: =IF(HC5<>0,HC5,IF($GT5="out",$GR5/12,0)) -> -7186.5523 | HE5: =IF(HD5<>0,HD5,IF($GT5="nov",$GR5/12,0)) -> -7186.5523 | HF5: =IF(HE5<>0,HE5,IF($GT5="dez",$GR5/12,0)) -> -7186.5523 | HG5: =SUM(GU5:HF5) -> -50305.866 | HH5: =IF(GT5=0,"",IF(GR5=0,0,GR5-HG5)) -> -35932.761 | HI5: =IF(HG5=0,"",IF(HG5=FZ5,0,IF(HG5<FZ5,1,2))) -> #REF! | HK5: 1 | HL5: 1 | HM5: =IF($GB5<>"",$GB5,IFERROR(T(INDEX('MATRIZ 2X2'!$J$20:$J$367,MATCH(UPPER(TRIM(SUBSTITUTE(IF(ISNUMBER(VALUE(LEFT(TRIM(J5),6))),MID(TRIM(J5),FIND(" ",TRIM(J5))+1,300),TRIM(J5)),".",""))),'MATRIZ 2X2'!$P$20:$P$367,0))),"")) -> JUN | HN5: =IFERROR(INDEX('MATRIZ 2X2'!$G$20:$G$367,MATCH(UPPER(TRIM(SUBSTITUTE(IF(ISNUMBER(VALUE(LEFT(TRIM(J5),6))),MID(TRIM(J5),FIND(" ",TRIM(J5))+1,300),TRIM(J5)),".",""))),'MATRIZ 2X2'!$P$20:$P$367,0)),"")
A6: =TRIM(E6) -> 171430 | B6: LABORATORIO | C6: PRÉ ANALITICO | D6: ESCALPE | E6: 171430 | F6: ESCALPE COL SANG DISP SEGUR 23GX7 367256 | G6: CE | H6: 2045 | I6: HAM-CD FORTALEZA | J6: BECTON DICKINSON IND CIRURG LTDA | K6: 344600 | L6: =M6*K6 -> 951078.12 | M6: 2.7599481 | N6: 2.3 | O6: =N6*K6 -> 792580 | P6: BECTON DICKINSON INDUSTRIAS CIRURGI | Q6: 2.8630492 | R6: =IF($Q6="",0,$Q6*$K6) -> 986606.75 | S6: =R6/12 -> 82217.229 | T6: =IF($Q6=0,0,$R6-$L6) -> 35528.631 | U6: =IFERROR(IF(OR(Q6="",Q6=0),"",T6/L6),"") -> 0.037356164 | V6: 2.863338 | W6: =IF($V6="",0,$V6*$K6) -> 986706.27 | X6: =W6/12 -> 82225.523 | Y6: =IF($V6=0,0,$W6-$L6) -> 35628.152 | Z6: =IFERROR(IF(OR(V6="",V6=0),"",Y6/L6),"") -> 0.037460805 | AA6: 0.12 | AB6: =Q6-Q6*AA6 -> 2.5194833 | AC6: =AB6*K6 -> 868213.94 | AD6: =AC6-R6 -> -118392.81 | AE6: =IF(R6=0,"",AD6/R6) -> -0.12 | AF6: =AC6-W6 -> -118492.33 | AG6: =AF6/W6 -> -0.12008876 | AH6: FINALIZADO | AJ6: =IFERROR(INDEX($AO$1:$FM$1,MATCH($AK6,$AO6:$FM6,0)),"") -> BD COLETA | AK6: =MIN(AO6:FM6) -> 2.12 | AL6: =AK6*K6 -> 730552 | AM6: =IF(OR(AK6="",AK6=0),0,AL6-$W6) -> -256154.27 | AN6: =IF(AK6=0,"",AM6/$W6) -> -0.2596054 | AR6: 2.12 | FN6: =$AD6*#REF! -> #REF! | FO6: =$AD6*#REF! -> #REF! | FP6: =$AD6*#REF! -> #REF! | FQ6: =$AD6*#REF! -> #REF! | FR6: =$AD6*#REF! -> #REF! | FS6: =$AD6*#REF! -> #REF! | FT6: =$AD6*#REF! -> #REF! | FU6: =$AD6*#REF! -> #REF! | ... FY6: =$AD6*#REF! -> #REF! | FZ6: =SUM(FN6:FY6) -> #REF! | GA6: =AD6-FZ6 -> #REF! | GB6: JUN | GC6: =IF($GB6="jan",$AM6/12,0) -> 0 | GD6: =IF(GC6<>0,GC6,IF($GB6="fev",$AM6/12,0)) -> 0 | GE6: =IF(GD6<>0,GD6,IF($GB6="mar",$AM6/12,0)) -> 0 | GF6: =IF(GE6<>0,GE6,IF($GB6="abr",$AM6/12,0)) -> 0 | GG6: =IF(GF6<>0,GF6,IF($GB6="mai",$AM6/12,0)) -> 0 | GH6: =IF(GG6<>0,GG6,IF($GB6="jun",$AM6/12,0)) -> -21346.189 | GI6: =IF(GH6<>0,GH6,IF($GB6="jul",$AM6/12,0)) -> -21346.189 | GJ6: =IF(GI6<>0,GI6,IF($GB6="ago",$AM6/12,0)) -> -21346.189 | GK6: =IF(GJ6<>0,GJ6,IF($GB6="set",$AM6/12,0)) -> -21346.189 | GL6: =IF(GK6<>0,GK6,IF($GB6="out",$AM6/12,0)) -> -21346.189 | GM6: =IF(GL6<>0,GL6,IF($GB6="nov",$AM6/12,0)) -> -21346.189 | GN6: =IF(GM6<>0,GM6,IF($GB6="dez",$AM6/12,0)) -> -21346.189 | GO6: =SUM(GC6:GN6) -> -149423.33 | GP6: =IF(GB6="","",IF(AM6=0,0,AM6-GO6)) -> -106730.95 | GQ6: =IF(GO6=0,"",IF(GO6=FZ6,0,IF(GO6<FZ6,1,2))) -> #REF! | GR6: =IF(OR(AK6="",AK6=0),0,AL6-$W6) -> -256154.27 | GS6: =IF(AK6=0,"",GR6/$W6) -> -0.2596054 | GT6: =GB6 -> JUN | GU6: =IF($GT6="jan",$GR6/12,0) -> 0 | GV6: =IF(GU6<>0,GU6,IF($GT6="fev",$GR6/12,0)) -> 0 | GW6: =IF(GV6<>0,GV6,IF($GT6="mar",$GR6/12,0)) -> 0 | GX6: =IF(GW6<>0,GW6,IF($GT6="abr",$GR6/12,0)) -> 0 | GY6: =IF(GX6<>0,GX6,IF($GT6="mai",$GR6/12,0)) -> 0 | GZ6: =IF(GY6<>0,GY6,IF($GT6="jun",$GR6/12,0)) -> -21346.189 | HA6: =IF(GZ6<>0,GZ6,IF($GT6="jul",$GR6/12,0)) -> -21346.189 | HB6: =IF(HA6<>0,HA6,IF($GT6="ago",$GR6/12,0)) -> -21346.189 | HC6: =IF(HB6<>0,HB6,IF($GT6="set",$GR6/12,0)) -> -21346.189 | HD6: =IF(HC6<>0,HC6,IF($GT6="out",$GR6/12,0)) -> -21346.189 | HE6: =IF(HD6<>0,HD6,IF($GT6="nov",$GR6/12,0)) -> -21346.189 | HF6: =IF(HE6<>0,HE6,IF($GT6="dez",$GR6/12,0)) -> -21346.189 | HG6: =SUM(GU6:HF6) -> -149423.33 | HH6: =IF(GT6=0,"",IF(GR6=0,0,GR6-HG6)) -> -106730.95 | HI6: =IF(HG6=0,"",IF(HG6=FZ6,0,IF(HG6<FZ6,1,2))) -> #REF! | HK6: 1 | HL6: 1 | HM6: =IF($GB6<>"",$GB6,IFERROR(T(INDEX('MATRIZ 2X2'!$J$20:$J$367,MATCH(UPPER(TRIM(SUBSTITUTE(IF(ISNUMBER(VALUE(LEFT(TRIM(J6),6))),MID(TRIM(J6),FIND(" ",TRIM(J6))+1,300),TRIM(J6)),".",""))),'MATRIZ 2X2'!$P$20:$P$367,0))),"")) -> JUN | HN6: =IFERROR(INDEX('MATRIZ 2X2'!$G$20:$G$367,MATCH(UPPER(TRIM(SUBSTITUTE(IF(ISNUMBER(VALUE(LEFT(TRIM(J6),6))),MID(TRIM(J6),FIND(" ",TRIM(J6))+1,300),TRIM(J6)),".",""))),'MATRIZ 2X2'!$P$20:$P$367,0)),"")
A7: =TRIM(E7) -> 211181 | B7: LABORATORIO | C7: PRÉ ANALITICO | D7: TUBO | E7: 211181 | F7: TUBO HEMATOLOGIA AM SORO 3.5ML BD 360059 | G7: SP | H7: 3069 | I7: NDI-CD LAPA | J7: BECTON DICKINSON IND CIRURG LTDA | K7: 1534100 | L7: =M7*K7 -> 859096 | M7: 0.56 | N7: 0.58 | O7: =N7*K7 -> 889778 | P7: BECTON DICKINSON INDUSTRIAS CIRURGI | Q7: 0.56121084 | R7: =IF($Q7="",0,$Q7*$K7) -> 860953.55 | S7: =R7/12 -> 71746.129 | T7: =IF($Q7=0,0,$R7-$L7) -> 1857.547 | U7: =IFERROR(IF(OR(Q7="",Q7=0),"",T7/L7),"") -> 0.0021622112 | V7: 0.56086563 | W7: =IF($V7="",0,$V7*$K7) -> 860423.96 | X7: =W7/12 -> 71701.997 | Y7: =IF($V7=0,0,$W7-$L7) -> 1327.96 | Z7: =IFERROR(IF(OR(V7="",V7=0),"",Y7/L7),"") -> 0.0015457644 | AA7: 0.12 | AB7: =Q7-Q7*AA7 -> 0.49386554 | AC7: =AB7*K7 -> 757639.12 | AD7: =AC7-R7 -> -103314.43 | AE7: =IF(R7=0,"",AD7/R7) -> -0.12 | AF7: =AC7-W7 -> -102784.84 | AG7: =AF7/W7 -> -0.11945836 | AH7: FINALIZADO | AJ7: =IFERROR(INDEX($AO$1:$FM$1,MATCH($AK7,$AO7:$FM7,0)),"") -> BD COLETA | AK7: =MIN(AO7:FM7) -> 0.58 | AL7: =AK7*K7 -> 889778 | AM7: =IF(OR(AK7="",AK7=0),0,AL7-$W7) -> 29354.04 | AN7: =IF(AK7=0,"",AM7/$W7) -> 0.034115786 | AR7: 0.58 | FN7: =$AD7*#REF! -> #REF! | FO7: =$AD7*#REF! -> #REF! | FP7: =$AD7*#REF! -> #REF! | FQ7: =$AD7*#REF! -> #REF! | FR7: =$AD7*#REF! -> #REF! | FS7: =$AD7*#REF! -> #REF! | FT7: =$AD7*#REF! -> #REF! | FU7: =$AD7*#REF! -> #REF! | ... FY7: =$AD7*#REF! -> #REF! | FZ7: =SUM(FN7:FY7) -> #REF! | GA7: =AD7-FZ7 -> #REF! | GB7: JUN | GC7: =IF($GB7="jan",$AM7/12,0) -> 0 | GD7: =IF(GC7<>0,GC7,IF($GB7="fev",$AM7/12,0)) -> 0 | GE7: =IF(GD7<>0,GD7,IF($GB7="mar",$AM7/12,0)) -> 0 | GF7: =IF(GE7<>0,GE7,IF($GB7="abr",$AM7/12,0)) -> 0 | GG7: =IF(GF7<>0,GF7,IF($GB7="mai",$AM7/12,0)) -> 0 | GH7: =IF(GG7<>0,GG7,IF($GB7="jun",$AM7/12,0)) -> 2446.17 | GI7: =IF(GH7<>0,GH7,IF($GB7="jul",$AM7/12,0)) -> 2446.17 | GJ7: =IF(GI7<>0,GI7,IF($GB7="ago",$AM7/12,0)) -> 2446.17 | GK7: =IF(GJ7<>0,GJ7,IF($GB7="set",$AM7/12,0)) -> 2446.17 | GL7: =IF(GK7<>0,GK7,IF($GB7="out",$AM7/12,0)) -> 2446.17 | GM7: =IF(GL7<>0,GL7,IF($GB7="nov",$AM7/12,0)) -> 2446.17 | GN7: =IF(GM7<>0,GM7,IF($GB7="dez",$AM7/12,0)) -> 2446.17 | GO7: =SUM(GC7:GN7) -> 17123.19 | GP7: =IF(GB7="","",IF(AM7=0,0,AM7-GO7)) -> 12230.85 | GQ7: =IF(GO7=0,"",IF(GO7=FZ7,0,IF(GO7<FZ7,1,2))) -> #REF! | GR7: =IF(OR(AK7="",AK7=0),0,AL7-$W7) -> 29354.04 | GS7: =IF(AK7=0,"",GR7/$W7) -> 0.034115786 | GT7: =GB7 -> JUN | GU7: =IF($GT7="jan",$GR7/12,0) -> 0 | GV7: =IF(GU7<>0,GU7,IF($GT7="fev",$GR7/12,0)) -> 0 | GW7: =IF(GV7<>0,GV7,IF($GT7="mar",$GR7/12,0)) -> 0 | GX7: =IF(GW7<>0,GW7,IF($GT7="abr",$GR7/12,0)) -> 0 | GY7: =IF(GX7<>0,GX7,IF($GT7="mai",$GR7/12,0)) -> 0 | GZ7: =IF(GY7<>0,GY7,IF($GT7="jun",$GR7/12,0)) -> 2446.17 | HA7: =IF(GZ7<>0,GZ7,IF($GT7="jul",$GR7/12,0)) -> 2446.17 | HB7: =IF(HA7<>0,HA7,IF($GT7="ago",$GR7/12,0)) -> 2446.17 | HC7: =IF(HB7<>0,HB7,IF($GT7="set",$GR7/12,0)) -> 2446.17 | HD7: =IF(HC7<>0,HC7,IF($GT7="out",$GR7/12,0)) -> 2446.17 | HE7: =IF(HD7<>0,HD7,IF($GT7="nov",$GR7/12,0)) -> 2446.17 | HF7: =IF(HE7<>0,HE7,IF($GT7="dez",$GR7/12,0)) -> 2446.17 | HG7: =SUM(GU7:HF7) -> 17123.19 | HH7: =IF(GT7=0,"",IF(GR7=0,0,GR7-HG7)) -> 12230.85 | HI7: =IF(HG7=0,"",IF(HG7=FZ7,0,IF(HG7<FZ7,1,2))) -> #REF! | HK7: 1 | HL7: 1 | HM7: =IF($GB7<>"",$GB7,IFERROR(T(INDEX('MATRIZ 2X2'!$J$20:$J$367,MATCH(UPPER(TRIM(SUBSTITUTE(IF(ISNUMBER(VALUE(LEFT(TRIM(J7),6))),MID(TRIM(J7),FIND(" ",TRIM(J7))+1,300),TRIM(J7)),".",""))),'MATRIZ 2X2'!$P$20:$P$367,0))),"")) -> JUN | HN7: =IFERROR(INDEX('MATRIZ 2X2'!$G$20:$G$367,MATCH(UPPER(TRIM(SUBSTITUTE(IF(ISNUMBER(VALUE(LEFT(TRIM(J7),6))),MID(TRIM(J7),FIND(" ",TRIM(J7))+1,300),TRIM(J7)),".",""))),'MATRIZ 2X2'!$P$20:$P$367,0)),"")
A8: =TRIM(E8) -> 171430 | B8: LABORATORIO | C8: PRÉ ANALITICO | D8: ESCALPE | E8: 171430 | F8: ESCALPE COL SANG DISP SEGUR 23GX7 367256 | G8: SP | H8: 3069 | I8: NDI-CD LAPA | J8: BECTON DICKINSON IND CIRURG LTDA | K8: 302800 | L8: =M8*K8 -> 834624.52 | M8: 2.7563557 | N8: 2.3 | O8: =N8*K8 -> 696440 | P8: BECTON DICKINSON INDUSTRIAS CIRURGI | Q8: 2.8630492 | R8: =IF($Q8="",0,$Q8*$K8) -> 866931.29 | S8: =R8/12 -> 72244.275 | T8: =IF($Q8=0,0,$R8-$L8) -> 32306.775 | U8: =IFERROR(IF(OR(Q8="",Q8=0),"",T8/L8),"") -> 0.038708154 | V8: 2.863338 | W8: =IF($V8="",0,$V8*$K8) -> 867018.74 | X8: =W8/12 -> 72251.562 | Y8: =IF($V8=0,0,$W8-$L8) -> 32394.224 | Z8: =IFERROR(IF(OR(V8="",V8=0),"",Y8/L8),"") -> 0.038812931 | AA8: 0.12 | AB8: =Q8-Q8*AA8 -> 2.5194833 | AC8: =AB8*K8 -> 762899.54 | AD8: =AC8-R8 -> -104031.76 | AE8: =IF(R8=0,"",AD8/R8) -> -0.12 | AF8: =AC8-W8 -> -104119.2 | AG8: =AF8/W8 -> -0.12008876 | AH8: FINALIZADO | AJ8: =IFERROR(INDEX($AO$1:$FM$1,MATCH($AK8,$AO8:$FM8,0)),"") -> BD COLETA | AK8: =MIN(AO8:FM8) -> 2.12 | AL8: =AK8*K8 -> 641936 | AM8: =IF(OR(AK8="",AK8=0),0,AL8-$W8) -> -225082.74 | AN8: =IF(AK8=0,"",AM8/$W8) -> -0.2596054 | AR8: 2.12 | FN8: =$AD8*#REF! -> #REF! | FO8: =$AD8*#REF! -> #REF! | FP8: =$AD8*#REF! -> #REF! | FQ8: =$AD8*#REF! -> #REF! | FR8: =$AD8*#REF! -> #REF! | FS8: =$AD8*#REF! -> #REF! | FT8: =$AD8*#REF! -> #REF! | FU8: =$AD8*#REF! -> #REF! | ... FY8: =$AD8*#REF! -> #REF! | FZ8: =SUM(FN8:FY8) -> #REF! | GA8: =AD8-FZ8 -> #REF! | GB8: JUN | GC8: =IF($GB8="jan",$AM8/12,0) -> 0 | GD8: =IF(GC8<>0,GC8,IF($GB8="fev",$AM8/12,0)) -> 0 | GE8: =IF(GD8<>0,GD8,IF($GB8="mar",$AM8/12,0)) -> 0 | GF8: =IF(GE8<>0,GE8,IF($GB8="abr",$AM8/12,0)) -> 0 | GG8: =IF(GF8<>0,GF8,IF($GB8="mai",$AM8/12,0)) -> 0 | GH8: =IF(GG8<>0,GG8,IF($GB8="jun",$AM8/12,0)) -> -18756.895 | GI8: =IF(GH8<>0,GH8,IF($GB8="jul",$AM8/12,0)) -> -18756.895 | GJ8: =IF(GI8<>0,GI8,IF($GB8="ago",$AM8/12,0)) -> -18756.895 | GK8: =IF(GJ8<>0,GJ8,IF($GB8="set",$AM8/12,0)) -> -18756.895 | GL8: =IF(GK8<>0,GK8,IF($GB8="out",$AM8/12,0)) -> -18756.895 | GM8: =IF(GL8<>0,GL8,IF($GB8="nov",$AM8/12,0)) -> -18756.895 | GN8: =IF(GM8<>0,GM8,IF($GB8="dez",$AM8/12,0)) -> -18756.895 | GO8: =SUM(GC8:GN8) -> -131298.27 | GP8: =IF(GB8="","",IF(AM8=0,0,AM8-GO8)) -> -93784.477 | GQ8: =IF(GO8=0,"",IF(GO8=FZ8,0,IF(GO8<FZ8,1,2))) -> #REF! | GR8: =IF(OR(AK8="",AK8=0),0,AL8-$W8) -> -225082.74 | GS8: =IF(AK8=0,"",GR8/$W8) -> -0.2596054 | GT8: =GB8 -> JUN | GU8: =IF($GT8="jan",$GR8/12,0) -> 0 | GV8: =IF(GU8<>0,GU8,IF($GT8="fev",$GR8/12,0)) -> 0 | GW8: =IF(GV8<>0,GV8,IF($GT8="mar",$GR8/12,0)) -> 0 | GX8: =IF(GW8<>0,GW8,IF($GT8="abr",$GR8/12,0)) -> 0 | GY8: =IF(GX8<>0,GX8,IF($GT8="mai",$GR8/12,0)) -> 0 | GZ8: =IF(GY8<>0,GY8,IF($GT8="jun",$GR8/12,0)) -> -18756.895 | HA8: =IF(GZ8<>0,GZ8,IF($GT8="jul",$GR8/12,0)) -> -18756.895 | HB8: =IF(HA8<>0,HA8,IF($GT8="ago",$GR8/12,0)) -> -18756.895 | HC8: =IF(HB8<>0,HB8,IF($GT8="set",$GR8/12,0)) -> -18756.895 | HD8: =IF(HC8<>0,HC8,IF($GT8="out",$GR8/12,0)) -> -18756.895 | HE8: =IF(HD8<>0,HD8,IF($GT8="nov",$GR8/12,0)) -> -18756.895 | HF8: =IF(HE8<>0,HE8,IF($GT8="dez",$GR8/12,0)) -> -18756.895 | HG8: =SUM(GU8:HF8) -> -131298.27 | HH8: =IF(GT8=0,"",IF(GR8=0,0,GR8-HG8)) -> -93784.477 | HI8: =IF(HG8=0,"",IF(HG8=FZ8,0,IF(HG8<FZ8,1,2))) -> #REF! | HK8: 0 | HL8: 0 | HM8: =IF($GB8<>"",$GB8,IFERROR(T(INDEX('MATRIZ 2X2'!$J$20:$J$367,MATCH(UPPER(TRIM(SUBSTITUTE(IF(ISNUMBER(VALUE(LEFT(TRIM(J8),6))),MID(TRIM(J8),FIND(" ",TRIM(J8))+1,300),TRIM(J8)),".",""))),'MATRIZ 2X2'!$P$20:$P$367,0))),"")) -> JUN | HN8: =IFERROR(INDEX('MATRIZ 2X2'!$G$20:$G$367,MATCH(UPPER(TRIM(SUBSTITUTE(IF(ISNUMBER(VALUE(LEFT(TRIM(J8),6))),MID(TRIM(J8),FIND(" ",TRIM(J8))+1,300),TRIM(J8)),".",""))),'MATRIZ 2X2'!$P$20:$P$367,0)),"")
A9: =TRIM(E9) -> 152794 | B9: LABORATORIO | C9: PRÉ ANALITICO | D9: TUBO | E9: 152794 | F9: TUBO 13X75MM C/CIT SODIO 2.7ML 363083 | G9: SP | H9: 3069 | I9: NDI-CD LAPA | J9: BECTON DICKINSON IND CIRURG LTDA | K9: 641900 | L9: =M9*K9 -> 783118 | M9: 1.22 | N9: 1.22 | O9: =N9*K9 -> 783118 | P9: BECTON DICKINSON INDUSTRIAS CIRURGI | Q9: 1.3888301 | R9: =IF($Q9="",0,$Q9*$K9) -> 891490.06 | S9: =R9/12 -> 74290.839 | T9: =IF($Q9=0,0,$R9-$L9) -> 108372.06 | U9: =IFERROR(IF(OR(Q9="",Q9=0),"",T9/L9),"") -> 0.13838536 | V9: 1.5089743 | W9: =IF($V9="",0,$V9*$K9) -> 968610.62 | X9: =W9/12 -> 80717.551 | Y9: =IF($V9=0,0,$W9-$L9) -> 185492.62 | Z9: =IFERROR(IF(OR(V9="",V9=0),"",Y9/L9),"") -> 0.2368642 | AA9: 0.12 | AB9: =Q9-Q9*AA9 -> 1.2221705 | AC9: =AB9*K9 -> 784511.26 | AD9: =AC9-R9 -> -106978.81 | AE9: =IF(R9=0,"",AD9/R9) -> -0.12 | AF9: =AC9-W9 -> -184099.36 | AG9: =AF9/W9 -> -0.19006539 | AH9: FINALIZADO | AJ9: =IFERROR(INDEX($AO$1:$FM$1,MATCH($AK9,$AO9:$FM9,0)),"") -> BD COLETA | AK9: =MIN(AO9:FM9) -> 1.22 | AL9: =AK9*K9 -> 783118 | AM9: =IF(OR(AK9="",AK9=0),0,AL9-$W9) -> -185492.62 | AN9: =IF(AK9=0,"",AM9/$W9) -> -0.1915038 | AR9: 1.22 | FN9: =$AD9*#REF! -> #REF! | FO9: =$AD9*#REF! -> #REF! | FP9: =$AD9*#REF! -> #REF! | FQ9: =$AD9*#REF! -> #REF! | FR9: =$AD9*#REF! -> #REF! | FS9: =$AD9*#REF! -> #REF! | FT9: =$AD9*#REF! -> #REF! | FU9: =$AD9*#REF! -> #REF! | ... FY9: =$AD9*#REF! -> #REF! | FZ9: =SUM(FN9:FY9) -> #REF! | GA9: =AD9-FZ9 -> #REF! | GB9: JUN | GC9: =IF($GB9="jan",$AM9/12,0) -> 0 | GD9: =IF(GC9<>0,GC9,IF($GB9="fev",$AM9/12,0)) -> 0 | GE9: =IF(GD9<>0,GD9,IF($GB9="mar",$AM9/12,0)) -> 0 | GF9: =IF(GE9<>0,GE9,IF($GB9="abr",$AM9/12,0)) -> 0 | GG9: =IF(GF9<>0,GF9,IF($GB9="mai",$AM9/12,0)) -> 0 | GH9: =IF(GG9<>0,GG9,IF($GB9="jun",$AM9/12,0)) -> -15457.718 | GI9: =IF(GH9<>0,GH9,IF($GB9="jul",$AM9/12,0)) -> -15457.718 | GJ9: =IF(GI9<>0,GI9,IF($GB9="ago",$AM9/12,0)) -> -15457.718 | GK9: =IF(GJ9<>0,GJ9,IF($GB9="set",$AM9/12,0)) -> -15457.718 | GL9: =IF(GK9<>0,GK9,IF($GB9="out",$AM9/12,0)) -> -15457.718 | GM9: =IF(GL9<>0,GL9,IF($GB9="nov",$AM9/12,0)) -> -15457.718 | GN9: =IF(GM9<>0,GM9,IF($GB9="dez",$AM9/12,0)) -> -15457.718 | GO9: =SUM(GC9:GN9) -> -108204.03 | GP9: =IF(GB9="","",IF(AM9=0,0,AM9-GO9)) -> -77288.59 | GQ9: =IF(GO9=0,"",IF(GO9=FZ9,0,IF(GO9<FZ9,1,2))) -> #REF! | GR9: =IF(OR(AK9="",AK9=0),0,AL9-$W9) -> -185492.62 | GS9: =IF(AK9=0,"",GR9/$W9) -> -0.1915038 | GT9: =GB9 -> JUN | GU9: =IF($GT9="jan",$GR9/12,0) -> 0 | GV9: =IF(GU9<>0,GU9,IF($GT9="fev",$GR9/12,0)) -> 0 | GW9: =IF(GV9<>0,GV9,IF($GT9="mar",$GR9/12,0)) -> 0 | GX9: =IF(GW9<>0,GW9,IF($GT9="abr",$GR9/12,0)) -> 0 | GY9: =IF(GX9<>0,GX9,IF($GT9="mai",$GR9/12,0)) -> 0 | GZ9: =IF(GY9<>0,GY9,IF($GT9="jun",$GR9/12,0)) -> -15457.718 | HA9: =IF(GZ9<>0,GZ9,IF($GT9="jul",$GR9/12,0)) -> -15457.718 | HB9: =IF(HA9<>0,HA9,IF($GT9="ago",$GR9/12,0)) -> -15457.718 | HC9: =IF(HB9<>0,HB9,IF($GT9="set",$GR9/12,0)) -> -15457.718 | HD9: =IF(HC9<>0,HC9,IF($GT9="out",$GR9/12,0)) -> -15457.718 | HE9: =IF(HD9<>0,HD9,IF($GT9="nov",$GR9/12,0)) -> -15457.718 | HF9: =IF(HE9<>0,HE9,IF($GT9="dez",$GR9/12,0)) -> -15457.718 | HG9: =SUM(GU9:HF9) -> -108204.03 | HH9: =IF(GT9=0,"",IF(GR9=0,0,GR9-HG9)) -> -77288.59 | HI9: =IF(HG9=0,"",IF(HG9=FZ9,0,IF(HG9<FZ9,1,2))) -> #REF! | HK9: 1 | HL9: 1 | HM9: =IF($GB9<>"",$GB9,IFERROR(T(INDEX('MATRIZ 2X2'!$J$20:$J$367,MATCH(UPPER(TRIM(SUBSTITUTE(IF(ISNUMBER(VALUE(LEFT(TRIM(J9),6))),MID(TRIM(J9),FIND(" ",TRIM(J9))+1,300),TRIM(J9)),".",""))),'MATRIZ 2X2'!$P$20:$P$367,0))),"")) -> JUN | HN9: =IFERROR(INDEX('MATRIZ 2X2'!$G$20:$G$367,MATCH(UPPER(TRIM(SUBSTITUTE(IF(ISNUMBER(VALUE(LEFT(TRIM(J9),6))),MID(TRIM(J9),FIND(" ",TRIM(J9))+1,300),TRIM(J9)),".",""))),'MATRIZ 2X2'!$P$20:$P$367,0)),"")
A10: =TRIM(E10) -> 197223 | B10: LABORATORIO | C10: PRÉ ANALITICO | D10: ESCALPE | E10: 197223 | F10: BD VACUT UT/PB 23G 367392 SCALP 1 | G10: AM | H10: 2245 | I10: HAM-HOSP SAO LUCAS | J10: BECTON DICKINSON INDUSTRIAS CIRURGI | K10: 203100 | L10: =M10*K10 -> 761625 | M10: 3.75 | N10: 3.57 | O10: =N10*K10 -> 725067 | P10: BECTON DICKINSON INDUSTRIAS CIRURGI | Q10: 4.0070958 | R10: =IF($Q10="",0,$Q10*$K10) -> 813841.15 | S10: =R10/12 -> 67820.096 | T10: =IF($Q10=0,0,$R10-$L10) -> 52216.147 | U10: =IFERROR(IF(OR(Q10="",Q10=0),"",T10/L10),"") -> 0.068558867 | V10: 4.0914771 | W10: =IF($V10="",0,$V10*$K10) -> 830979 | X10: =W10/12 -> 69248.25 | Y10: =IF($V10=0,0,$W10-$L10) -> 69354.001 | Z10: =IFERROR(IF(OR(V10="",V10=0),"",Y10/L10),"") -> 0.091060562 | AA10: 0.12 | AB10: =Q10-Q10*AA10 -> 3.5262443 | AC10: =AB10*K10 -> 716180.21 | AD10: =AC10-R10 -> -97660.938 | AE10: =IF(R10=0,"",AD10/R10) -> -0.12 | AF10: =AC10-W10 -> -114798.79 | AG10: =AF10/W10 -> -0.13814885 | AH10: FINALIZADO | AJ10: =IFERROR(INDEX($AO$1:$FM$1,MATCH($AK10,$AO10:$FM10,0)),"") -> BD COLETA | AK10: =MIN(AO10:FM10) -> 3.39 | AL10: =AK10*K10 -> 688509 | AM10: =IF(OR(AK10="",AK10=0),0,AL10-$W10) -> -142470 | AN10: =IF(AK10=0,"",AM10/$W10) -> -0.17144838 | AR10: 3.39 | BH10: 3.68 | BY10: 10.54 | BZ10: BD | FN10: =$AD10*#REF! -> #REF! | FO10: =$AD10*#REF! -> #REF! | FP10: =$AD10*#REF! -> #REF! | FQ10: =$AD10*#REF! -> #REF! | FR10: =$AD10*#REF! -> #REF! | FS10: =$AD10*#REF! -> #REF! | FT10: =$AD10*#REF! -> #REF! | FU10: =$AD10*#REF! -> #REF! | ... FY10: =$AD10*#REF! -> #REF! | FZ10: =SUM(FN10:FY10) -> #REF! | GA10: =AD10-FZ10 -> #REF! | GB10: JUN | GC10: =IF($GB10="jan",$AM10/12,0) -> 0 | GD10: =IF(GC10<>0,GC10,IF($GB10="fev",$AM10/12,0)) -> 0 | GE10: =IF(GD10<>0,GD10,IF($GB10="mar",$AM10/12,0)) -> 0 | GF10: =IF(GE10<>0,GE10,IF($GB10="abr",$AM10/12,0)) -> 0 | GG10: =IF(GF10<>0,GF10,IF($GB10="mai",$AM10/12,0)) -> 0 | GH10: =IF(GG10<>0,GG10,IF($GB10="jun",$AM10/12,0)) -> -11872.5 | GI10: =IF(GH10<>0,GH10,IF($GB10="jul",$AM10/12,0)) -> -11872.5 | GJ10: =IF(GI10<>0,GI10,IF($GB10="ago",$AM10/12,0)) -> -11872.5 | GK10: =IF(GJ10<>0,GJ10,IF($GB10="set",$AM10/12,0)) -> -11872.5 | GL10: =IF(GK10<>0,GK10,IF($GB10="out",$AM10/12,0)) -> -11872.5 | GM10: =IF(GL10<>0,GL10,IF($GB10="nov",$AM10/12,0)) -> -11872.5 | GN10: =IF(GM10<>0,GM10,IF($GB10="dez",$AM10/12,0)) -> -11872.5 | GO10: =SUM(GC10:GN10) -> -83107.5 | GP10: =IF(GB10="","",IF(AM10=0,0,AM10-GO10)) -> -59362.5 | GQ10: =IF(GO10=0,"",IF(GO10=FZ10,0,IF(GO10<FZ10,1,2))) -> #REF! | GR10: =IF(OR(AK10="",AK10=0),0,AL10-$W10) -> -142470 | GS10: =IF(AK10=0,"",GR10/$W10) -> -0.17144838 | GT10: =GB10 -> JUN | GU10: =IF($GT10="jan",$GR10/12,0) -> 0 | GV10: =IF(GU10<>0,GU10,IF($GT10="fev",$GR10/12,0)) -> 0 | GW10: =IF(GV10<>0,GV10,IF($GT10="mar",$GR10/12,0)) -> 0 | GX10: =IF(GW10<>0,GW10,IF($GT10="abr",$GR10/12,0)) -> 0 | GY10: =IF(GX10<>0,GX10,IF($GT10="mai",$GR10/12,0)) -> 0 | GZ10: =IF(GY10<>0,GY10,IF($GT10="jun",$GR10/12,0)) -> -11872.5 | HA10: =IF(GZ10<>0,GZ10,IF($GT10="jul",$GR10/12,0)) -> -11872.5 | HB10: =IF(HA10<>0,HA10,IF($GT10="ago",$GR10/12,0)) -> -11872.5 | HC10: =IF(HB10<>0,HB10,IF($GT10="set",$GR10/12,0)) -> -11872.5 | HD10: =IF(HC10<>0,HC10,IF($GT10="out",$GR10/12,0)) -> -11872.5 | HE10: =IF(HD10<>0,HD10,IF($GT10="nov",$GR10/12,0)) -> -11872.5 | HF10: =IF(HE10<>0,HE10,IF($GT10="dez",$GR10/12,0)) -> -11872.5 | HG10: =SUM(GU10:HF10) -> -83107.5 | HH10: =IF(GT10=0,"",IF(GR10=0,0,GR10-HG10)) -> -59362.5 | HI10: =IF(HG10=0,"",IF(HG10=FZ10,0,IF(HG10<FZ10,1,2))) -> #REF! | HK10: 1 | HL10: 1 | HM10: =IF($GB10<>"",$GB10,IFERROR(T(INDEX('MATRIZ 2X2'!$J$20:$J$367,MATCH(UPPER(TRIM(SUBSTITUTE(IF(ISNUMBER(VALUE(LEFT(TRIM(J10),6))),MID(TRIM(J10),FIND(" ",TRIM(J10))+1,300),TRIM(J10)),".",""))),'MATRIZ 2X2'!$P$20:$P$367,0))),"")) -> JUN | HN10: =IFERROR(INDEX('MATRIZ 2X2'!$G$20:$G$367,MATCH(UPPER(TRIM(SUBSTITUTE(IF(ISNUMBER(VALUE(LEFT(TRIM(J10),6))),MID(TRIM(J10),FIND(" ",TRIM(J10))+1,300),TRIM(J10)),".",""))),'MATRIZ 2X2'!$P$20:$P$367,0)),"")
A11: =TRIM(E11) -> 171430 | B11: LABORATORIO | C11: PRÉ ANALITICO | D11: ESCALPE | E11: 171430 | F11: ESCALPE COL SANG DISP SEGUR 23GX7 367256 | G11: PE | H11: 2044 | I11: HAM-CD RECIFE | J11: BECTON DICKINSON IND CIRURG LTDA | K11: 228450 | L11: =M11*K11 -> 630522 | M11: 2.76 | N11: 2.3 | O11: =N11*K11 -> 525435 | P11: BECTON DICKINSON INDUSTRIAS CIRURGI | Q11: 2.8630492 | R11: =IF($Q11="",0,$Q11*$K11) -> 654063.59 | S11: =R11/12 -> 54505.299 | T11: =IF($Q11=0,0,$R11-$L11) -> 23541.587 | U11: =IFERROR(IF(OR(Q11="",Q11=0),"",T11/L11),"") -> 0.037336663 | V11: 2.863338 | W11: =IF($V11="",0,$V11*$K11) -> 654129.56 | X11: =W11/12 -> 54510.797 | Y11: =IF($V11=0,0,$W11-$L11) -> 23607.564 | Z11: =IFERROR(IF(OR(V11="",V11=0),"",Y11/L11),"") -> 0.037441302 | AA11: 0.12 | AB11: =Q11-Q11*AA11 -> 2.5194833 | AC11: =AB11*K11 -> 575575.96 | AD11: =AC11-R11 -> -78487.63 | AE11: =IF(R11=0,"",AD11/R11) -> -0.12 | AF11: =AC11-W11 -> -78553.607 | AG11: =AF11/W11 -> -0.12008876 | AH11: FINALIZADO | AJ11: =IFERROR(INDEX($AO$1:$FM$1,MATCH($AK11,$AO11:$FM11,0)),"") -> BD COLETA | AK11: =MIN(AO11:FM11) -> 2.12 | AL11: =AK11*K11 -> 484314 | AM11: =IF(OR(AK11="",AK11=0),0,AL11-$W11) -> -169815.56 | AN11: =IF(AK11=0,"",AM11/$W11) -> -0.2596054 | AR11: 2.12 | FN11: =$AD11*#REF! -> #REF! | FO11: =$AD11*#REF! -> #REF! | FP11: =$AD11*#REF! -> #REF! | FQ11: =$AD11*#REF! -> #REF! | FR11: =$AD11*#REF! -> #REF! | FS11: =$AD11*#REF! -> #REF! | FT11: =$AD11*#REF! -> #REF! | FU11: =$AD11*#REF! -> #REF! | ... FY11: =$AD11*#REF! -> #REF! | FZ11: =SUM(FN11:FY11) -> #REF! | GA11: =AD11-FZ11 -> #REF! | GB11: JUN | GC11: =IF($GB11="jan",$AM11/12,0) -> 0 | GD11: =IF(GC11<>0,GC11,IF($GB11="fev",$AM11/12,0)) -> 0 | GE11: =IF(GD11<>0,GD11,IF($GB11="mar",$AM11/12,0)) -> 0 | GF11: =IF(GE11<>0,GE11,IF($GB11="abr",$AM11/12,0)) -> 0 | GG11: =IF(GF11<>0,GF11,IF($GB11="mai",$AM11/12,0)) -> 0 | GH11: =IF(GG11<>0,GG11,IF($GB11="jun",$AM11/12,0)) -> -14151.297 | GI11: =IF(GH11<>0,GH11,IF($GB11="jul",$AM11/12,0)) -> -14151.297 | GJ11: =IF(GI11<>0,GI11,IF($GB11="ago",$AM11/12,0)) -> -14151.297 | GK11: =IF(GJ11<>0,GJ11,IF($GB11="set",$AM11/12,0)) -> -14151.297 | GL11: =IF(GK11<>0,GK11,IF($GB11="out",$AM11/12,0)) -> -14151.297 | GM11: =IF(GL11<>0,GL11,IF($GB11="nov",$AM11/12,0)) -> -14151.297 | GN11: =IF(GM11<>0,GM11,IF($GB11="dez",$AM11/12,0)) -> -14151.297 | GO11: =SUM(GC11:GN11) -> -99059.079 | GP11: =IF(GB11="","",IF(AM11=0,0,AM11-GO11)) -> -70756.485 | GQ11: =IF(GO11=0,"",IF(GO11=FZ11,0,IF(GO11<FZ11,1,2))) -> #REF! | GR11: =IF(OR(AK11="",AK11=0),0,AL11-$W11) -> -169815.56 | GS11: =IF(AK11=0,"",GR11/$W11) -> -0.2596054 | GT11: =GB11 -> JUN | GU11: =IF($GT11="jan",$GR11/12,0) -> 0 | GV11: =IF(GU11<>0,GU11,IF($GT11="fev",$GR11/12,0)) -> 0 | GW11: =IF(GV11<>0,GV11,IF($GT11="mar",$GR11/12,0)) -> 0 | GX11: =IF(GW11<>0,GW11,IF($GT11="abr",$GR11/12,0)) -> 0 | GY11: =IF(GX11<>0,GX11,IF($GT11="mai",$GR11/12,0)) -> 0 | GZ11: =IF(GY11<>0,GY11,IF($GT11="jun",$GR11/12,0)) -> -14151.297 | HA11: =IF(GZ11<>0,GZ11,IF($GT11="jul",$GR11/12,0)) -> -14151.297 | HB11: =IF(HA11<>0,HA11,IF($GT11="ago",$GR11/12,0)) -> -14151.297 | HC11: =IF(HB11<>0,HB11,IF($GT11="set",$GR11/12,0)) -> -14151.297 | HD11: =IF(HC11<>0,HC11,IF($GT11="out",$GR11/12,0)) -> -14151.297 | HE11: =IF(HD11<>0,HD11,IF($GT11="nov",$GR11/12,0)) -> -14151.297 | HF11: =IF(HE11<>0,HE11,IF($GT11="dez",$GR11/12,0)) -> -14151.297 | HG11: =SUM(GU11:HF11) -> -99059.079 | HH11: =IF(GT11=0,"",IF(GR11=0,0,GR11-HG11)) -> -70756.485 | HI11: =IF(HG11=0,"",IF(HG11=FZ11,0,IF(HG11<FZ11,1,2))) -> #REF! | HK11: 0 | HL11: 0 | HM11: =IF($GB11<>"",$GB11,IFERROR(T(INDEX('MATRIZ 2X2'!$J$20:$J$367,MATCH(UPPER(TRIM(SUBSTITUTE(IF(ISNUMBER(VALUE(LEFT(TRIM(J11),6))),MID(TRIM(J11),FIND(" ",TRIM(J11))+1,300),TRIM(J11)),".",""))),'MATRIZ 2X2'!$P$20:$P$367,0))),"")) -> JUN | HN11: =IFERROR(INDEX('MATRIZ 2X2'!$G$20:$G$367,MATCH(UPPER(TRIM(SUBSTITUTE(IF(ISNUMBER(VALUE(LEFT(TRIM(J11),6))),MID(TRIM(J11),FIND(" ",TRIM(J11))+1,300),TRIM(J11)),".",""))),'MATRIZ 2X2'!$P$20:$P$367,0)),"")
A12: =TRIM(E12) -> 197223 | B12: LABORATORIO | C12: PRÉ ANALITICO | D12: ESCALPE | E12: 197223 | F12: BD VACUT UT/PB 23G 367392 SCALP 1 | G12: GO | H12: 2235 | I12: HAM-LABORATORIO JARDIM AMERICA | J12: BECTON DICKINSON INDUSTRIAS CIRURGI | K12: 130050 | L12: =M12*K12 -> 487687.5 | M12: 3.75 | N12: 3.57 | O12: =N12*K12 -> 464278.5 | P12: BECTON DICKINSON INDUSTRIAS CIRURGI | Q12: 4.0070958 | R12: =IF($Q12="",0,$Q12*$K12) -> 521122.8 | S12: =R12/12 -> 43426.9 | T12: =IF($Q12=0,0,$R12-$L12) -> 33435.302 | U12: =IFERROR(IF(OR(Q12="",Q12=0),"",T12/L12),"") -> 0.068558867 | V12: 4.0914771 | W12: =IF($V12="",0,$V12*$K12) -> 532096.6 | X12: =W12/12 -> 44341.383 | Y12: =IF($V12=0,0,$W12-$L12) -> 44409.098 | Z12: =IFERROR(IF(OR(V12="",V12=0),"",Y12/L12),"") -> 0.091060562 | AA12: 0.12 | AB12: =Q12-Q12*AA12 -> 3.5262443 | AC12: =AB12*K12 -> 458588.07 | AD12: =AC12-R12 -> -62534.736 | AE12: =IF(R12=0,"",AD12/R12) -> -0.12 | AF12: =AC12-W12 -> -73508.532 | AG12: =AF12/W12 -> -0.13814885 | AH12: FINALIZADO | AJ12: =IFERROR(INDEX($AO$1:$FM$1,MATCH($AK12,$AO12:$FM12,0)),"") -> BD COLETA | AK12: =MIN(AO12:FM12) -> 3.39 | AL12: =AK12*K12 -> 440869.5 | AM12: =IF(OR(AK12="",AK12=0),0,AL12-$W12) -> -91227.098 | AN12: =IF(AK12=0,"",AM12/$W12) -> -0.17144838 | AR12: 3.39 | BH12: 3.68 | BY12: 10.54 | BZ12: BD | FN12: =$AD12*#REF! -> #REF! | FO12: =$AD12*#REF! -> #REF! | FP12: =$AD12*#REF! -> #REF! | FQ12: =$AD12*#REF! -> #REF! | FR12: =$AD12*#REF! -> #REF! | FS12: =$AD12*#REF! -> #REF! | FT12: =$AD12*#REF! -> #REF! | FU12: =$AD12*#REF! -> #REF! | ... FY12: =$AD12*#REF! -> #REF! | FZ12: =SUM(FN12:FY12) -> #REF! | GA12: =AD12-FZ12 -> #REF! | GB12: JUN | GC12: =IF($GB12="jan",$AM12/12,0) -> 0 | GD12: =IF(GC12<>0,GC12,IF($GB12="fev",$AM12/12,0)) -> 0 | GE12: =IF(GD12<>0,GD12,IF($GB12="mar",$AM12/12,0)) -> 0 | GF12: =IF(GE12<>0,GE12,IF($GB12="abr",$AM12/12,0)) -> 0 | GG12: =IF(GF12<>0,GF12,IF($GB12="mai",$AM12/12,0)) -> 0 | GH12: =IF(GG12<>0,GG12,IF($GB12="jun",$AM12/12,0)) -> -7602.2582 | GI12: =IF(GH12<>0,GH12,IF($GB12="jul",$AM12/12,0)) -> -7602.2582 | GJ12: =IF(GI12<>0,GI12,IF($GB12="ago",$AM12/12,0)) -> -7602.2582 | GK12: =IF(GJ12<>0,GJ12,IF($GB12="set",$AM12/12,0)) -> -7602.2582 | GL12: =IF(GK12<>0,GK12,IF($GB12="out",$AM12/12,0)) -> -7602.2582 | GM12: =IF(GL12<>0,GL12,IF($GB12="nov",$AM12/12,0)) -> -7602.2582 | GN12: =IF(GM12<>0,GM12,IF($GB12="dez",$AM12/12,0)) -> -7602.2582 | GO12: =SUM(GC12:GN12) -> -53215.807 | GP12: =IF(GB12="","",IF(AM12=0,0,AM12-GO12)) -> -38011.291 | GQ12: =IF(GO12=0,"",IF(GO12=FZ12,0,IF(GO12<FZ12,1,2))) -> #REF! | GR12: =IF(OR(AK12="",AK12=0),0,AL12-$W12) -> -91227.098 | GS12: =IF(AK12=0,"",GR12/$W12) -> -0.17144838 | GT12: =GB12 -> JUN | GU12: =IF($GT12="jan",$GR12/12,0) -> 0 | GV12: =IF(GU12<>0,GU12,IF($GT12="fev",$GR12/12,0)) -> 0 | GW12: =IF(GV12<>0,GV12,IF($GT12="mar",$GR12/12,0)) -> 0 | GX12: =IF(GW12<>0,GW12,IF($GT12="abr",$GR12/12,0)) -> 0 | GY12: =IF(GX12<>0,GX12,IF($GT12="mai",$GR12/12,0)) -> 0 | GZ12: =IF(GY12<>0,GY12,IF($GT12="jun",$GR12/12,0)) -> -7602.2582 | HA12: =IF(GZ12<>0,GZ12,IF($GT12="jul",$GR12/12,0)) -> -7602.2582 | HB12: =IF(HA12<>0,HA12,IF($GT12="ago",$GR12/12,0)) -> -7602.2582 | HC12: =IF(HB12<>0,HB12,IF($GT12="set",$GR12/12,0)) -> -7602.2582 | HD12: =IF(HC12<>0,HC12,IF($GT12="out",$GR12/12,0)) -> -7602.2582 | HE12: =IF(HD12<>0,HD12,IF($GT12="nov",$GR12/12,0)) -> -7602.2582 | HF12: =IF(HE12<>0,HE12,IF($GT12="dez",$GR12/12,0)) -> -7602.2582 | HG12: =SUM(GU12:HF12) -> -53215.807 | HH12: =IF(GT12=0,"",IF(GR12=0,0,GR12-HG12)) -> -38011.291 | HI12: =IF(HG12=0,"",IF(HG12=FZ12,0,IF(HG12<FZ12,1,2))) -> #REF! | HK12: 0 | HL12: 0 | HM12: =IF($GB12<>"",$GB12,IFERROR(T(INDEX('MATRIZ 2X2'!$J$20:$J$367,MATCH(UPPER(TRIM(SUBSTITUTE(IF(ISNUMBER(VALUE(LEFT(TRIM(J12),6))),MID(TRIM(J12),FIND(" ",TRIM(J12))+1,300),TRIM(J12)),".",""))),'MATRIZ 2X2'!$P$20:$P$367,0))),"")) -> JUN | HN12: =IFERROR(INDEX('MATRIZ 2X2'!$G$20:$G$367,MATCH(UPPER(TRIM(SUBSTITUTE(IF(ISNUMBER(VALUE(LEFT(TRIM(J12),6))),MID(TRIM(J12),FIND(" ",TRIM(J12))+1,300),TRIM(J12)),".",""))),'MATRIZ 2X2'!$P$20:$P$367,0)),"")
A13: =TRIM(E13) -> 212235 | B13: LABORATORIO | C13: PRÉ ANALITICO | D13: TUBO | E13: 212235 | F13: VAC GEL SST 5ML 360060 TB 13X100MM | G13: AM | H13: 2245 | I13: HAM-HOSP SAO LUCAS | J13: BECTON DICKINSON INDUSTRIAS CIRURGI | K13: 755000 | L13: =M13*K13 -> 445446.1 | M13: 0.58999483 | N13: 0.64 | O13: =N13*K13 -> 483200 | P13: BECTON DICKINSON INDUSTRIAS CIRURGI | Q13: 0.62803448 | R13: =IF($Q13="",0,$Q13*$K13) -> 474166.03 | S13: =R13/12 -> 39513.836 | T13: =IF($Q13=0,0,$R13-$L13) -> 28719.933 | U13: =IFERROR(IF(OR(Q13="",Q13=0),"",T13/L13),"") -> 0.064474541 | V13: 0.63755821 | W13: =IF($V13="",0,$V13*$K13) -> 481356.45 | X13: =W13/12 -> 40113.037 | Y13: =IF($V13=0,0,$W13-$L13) -> 35910.347 | Z13: =IFERROR(IF(OR(V13="",V13=0),"",Y13/L13),"") -> 0.080616594 | AA13: 0.12 | AB13: =Q13-Q13*AA13 -> 0.55267034 | AC13: =AB13*K13 -> 417266.11 | AD13: =AC13-R13 -> -56899.924 | AE13: =IF(R13=0,"",AD13/R13) -> -0.12 | AF13: =AC13-W13 -> -64090.338 | AG13: =AF13/W13 -> -0.13314528 | AH13: FINALIZADO | AJ13: =IFERROR(INDEX($AO$1:$FM$1,MATCH($AK13,$AO13:$FM13,0)),"") -> BD COLETA | AK13: =MIN(AO13:FM13) -> 0.64 | AL13: =AK13*K13 -> 483200 | AM13: =IF(OR(AK13="",AK13=0),0,AL13-$W13) -> 1843.5526 | AN13: =IF(AK13=0,"",AM13/$W13) -> 0.0038299115 | AR13: 0.64 | FN13: =$AD13*#REF! -> #REF! | FO13: =$AD13*#REF! -> #REF! | FP13: =$AD13*#REF! -> #REF! | FQ13: =$AD13*#REF! -> #REF! | FR13: =$AD13*#REF! -> #REF! | FS13: =$AD13*#REF! -> #REF! | FT13: =$AD13*#REF! -> #REF! | FU13: =$AD13*#REF! -> #REF! | ... FY13: =$AD13*#REF! -> #REF! | FZ13: =SUM(FN13:FY13) -> #REF! | GA13: =AD13-FZ13 -> #REF! | GB13: JUN | GC13: =IF($GB13="jan",$AM13/12,0) -> 0 | GD13: =IF(GC13<>0,GC13,IF($GB13="fev",$AM13/12,0)) -> 0 | GE13: =IF(GD13<>0,GD13,IF($GB13="mar",$AM13/12,0)) -> 0 | GF13: =IF(GE13<>0,GE13,IF($GB13="abr",$AM13/12,0)) -> 0 | GG13: =IF(GF13<>0,GF13,IF($GB13="mai",$AM13/12,0)) -> 0 | GH13: =IF(GG13<>0,GG13,IF($GB13="jun",$AM13/12,0)) -> 153.62938 | GI13: =IF(GH13<>0,GH13,IF($GB13="jul",$AM13/12,0)) -> 153.62938 | GJ13: =IF(GI13<>0,GI13,IF($GB13="ago",$AM13/12,0)) -> 153.62938 | GK13: =IF(GJ13<>0,GJ13,IF($GB13="set",$AM13/12,0)) -> 153.62938 | GL13: =IF(GK13<>0,GK13,IF($GB13="out",$AM13/12,0)) -> 153.62938 | GM13: =IF(GL13<>0,GL13,IF($GB13="nov",$AM13/12,0)) -> 153.62938 | GN13: =IF(GM13<>0,GM13,IF($GB13="dez",$AM13/12,0)) -> 153.62938 | GO13: =SUM(GC13:GN13) -> 1075.4057 | GP13: =IF(GB13="","",IF(AM13=0,0,AM13-GO13)) -> 768.14691 | GQ13: =IF(GO13=0,"",IF(GO13=FZ13,0,IF(GO13<FZ13,1,2))) -> #REF! | GR13: =IF(OR(AK13="",AK13=0),0,AL13-$W13) -> 1843.5526 | GS13: =IF(AK13=0,"",GR13/$W13) -> 0.0038299115 | GT13: =GB13 -> JUN | GU13: =IF($GT13="jan",$GR13/12,0) -> 0 | GV13: =IF(GU13<>0,GU13,IF($GT13="fev",$GR13/12,0)) -> 0 | GW13: =IF(GV13<>0,GV13,IF($GT13="mar",$GR13/12,0)) -> 0 | GX13: =IF(GW13<>0,GW13,IF($GT13="abr",$GR13/12,0)) -> 0 | GY13: =IF(GX13<>0,GX13,IF($GT13="mai",$GR13/12,0)) -> 0 | GZ13: =IF(GY13<>0,GY13,IF($GT13="jun",$GR13/12,0)) -> 153.62938 | HA13: =IF(GZ13<>0,GZ13,IF($GT13="jul",$GR13/12,0)) -> 153.62938 | HB13: =IF(HA13<>0,HA13,IF($GT13="ago",$GR13/12,0)) -> 153.62938 | HC13: =IF(HB13<>0,HB13,IF($GT13="set",$GR13/12,0)) -> 153.62938 | HD13: =IF(HC13<>0,HC13,IF($GT13="out",$GR13/12,0)) -> 153.62938 | HE13: =IF(HD13<>0,HD13,IF($GT13="nov",$GR13/12,0)) -> 153.62938 | HF13: =IF(HE13<>0,HE13,IF($GT13="dez",$GR13/12,0)) -> 153.62938 | HG13: =SUM(GU13:HF13) -> 1075.4057 | HH13: =IF(GT13=0,"",IF(GR13=0,0,GR13-HG13)) -> 768.14691 | HI13: =IF(HG13=0,"",IF(HG13=FZ13,0,IF(HG13<FZ13,1,2))) -> #REF! | HK13: 0 | HL13: 0 | HM13: =IF($GB13<>"",$GB13,IFERROR(T(INDEX('MATRIZ 2X2'!$J$20:$J$367,MATCH(UPPER(TRIM(SUBSTITUTE(IF(ISNUMBER(VALUE(LEFT(TRIM(J13),6))),MID(TRIM(J13),FIND(" ",TRIM(J13))+1,300),TRIM(J13)),".",""))),'MATRIZ 2X2'!$P$20:$P$367,0))),"")) -> JUN | HN13: =IFERROR(INDEX('MATRIZ 2X2'!$G$20:$G$367,MATCH(UPPER(TRIM(SUBSTITUTE(IF(ISNUMBER(VALUE(LEFT(TRIM(J13),6))),MID(TRIM(J13),FIND(" ",TRIM(J13))+1,300),TRIM(J13)),".",""))),'MATRIZ 2X2'!$P$20:$P$367,0)),"")
A14: =TRIM(E14) -> 212236 | B14: LABORATORIO | C14: PRÉ ANALITICO | D14: TUBO | E14: 212236 | F14: VACUT K2 EDTA 4ML 360057 TB 13X75MM | G14: SP | H14: 3069 | I14: NDI-CD LAPA | J14: BECTON DICKINSON IND CIRURG LTDA | K14: 1148700 | L14: =M14*K14 -> 425019 | M14: 0.37 | N14: 0.39 | O14: =N14*K14 -> 447993 | P14: BECTON DICKINSON INDUSTRIAS CIRURGI | Q14: 0.38626284 | R14: =IF($Q14="",0,$Q14*$K14) -> 443700.12 | S14: =R14/12 -> 36975.01 | T14: =IF($Q14=0,0,$R14-$L14) -> 18681.124 | U14: =IFERROR(IF(OR(Q14="",Q14=0),"",T14/L14),"") -> 0.043953622 | V14: 0.39726512 | W14: =IF($V14="",0,$V14*$K14) -> 456338.45 | X14: =W14/12 -> 38028.204 | Y14: =IF($V14=0,0,$W14-$L14) -> 31319.447 | Z14: =IFERROR(IF(OR(V14="",V14=0),"",Y14/L14),"") -> 0.073689521 | AA14: 0.12 | AB14: =Q14-Q14*AA14 -> 0.3399113 | AC14: =AB14*K14 -> 390456.11 | AD14: =AC14-R14 -> -53244.015 | AE14: =IF(R14=0,"",AD14/R14) -> -0.12 | AF14: =AC14-W14 -> -65882.337 | AG14: =AF14/W14 -> -0.14437166 | AH14: FINALIZADO | AJ14: =IFERROR(INDEX($AO$1:$FM$1,MATCH($AK14,$AO14:$FM14,0)),"") -> BD COLETA | AK14: =MIN(AO14:FM14) -> 0.39 | AL14: =AK14*K14 -> 447993 | AM14: =IF(OR(AK14="",AK14=0),0,AL14-$W14) -> -8345.4466 | AN14: =IF(AK14=0,"",AM14/$W14) -> -0.018287845 | AR14: 0.39 | FN14: =$AD14*#REF! -> #REF! | FO14: =$AD14*#REF! -> #REF! | FP14: =$AD14*#REF! -> #REF! | FQ14: =$AD14*#REF! -> #REF! | FR14: =$AD14*#REF! -> #REF! | FS14: =$AD14*#REF! -> #REF! | FT14: =$AD14*#REF! -> #REF! | FU14: =$AD14*#REF! -> #REF! | ... FY14: =$AD14*#REF! -> #REF! | FZ14: =SUM(FN14:FY14) -> #REF! | GA14: =AD14-FZ14 -> #REF! | GB14: JUN | GC14: =IF($GB14="jan",$AM14/12,0) -> 0 | GD14: =IF(GC14<>0,GC14,IF($GB14="fev",$AM14/12,0)) -> 0 | GE14: =IF(GD14<>0,GD14,IF($GB14="mar",$AM14/12,0)) -> 0 | GF14: =IF(GE14<>0,GE14,IF($GB14="abr",$AM14/12,0)) -> 0 | GG14: =IF(GF14<>0,GF14,IF($GB14="mai",$AM14/12,0)) -> 0 | GH14: =IF(GG14<>0,GG14,IF($GB14="jun",$AM14/12,0)) -> -695.45388 | GI14: =IF(GH14<>0,GH14,IF($GB14="jul",$AM14/12,0)) -> -695.45388 | GJ14: =IF(GI14<>0,GI14,IF($GB14="ago",$AM14/12,0)) -> -695.45388 | GK14: =IF(GJ14<>0,GJ14,IF($GB14="set",$AM14/12,0)) -> -695.45388 | GL14: =IF(GK14<>0,GK14,IF($GB14="out",$AM14/12,0)) -> -695.45388 | GM14: =IF(GL14<>0,GL14,IF($GB14="nov",$AM14/12,0)) -> -695.45388 | GN14: =IF(GM14<>0,GM14,IF($GB14="dez",$AM14/12,0)) -> -695.45388 | GO14: =SUM(GC14:GN14) -> -4868.1772 | GP14: =IF(GB14="","",IF(AM14=0,0,AM14-GO14)) -> -3477.2694 | GQ14: =IF(GO14=0,"",IF(GO14=FZ14,0,IF(GO14<FZ14,1,2))) -> #REF! | GR14: =IF(OR(AK14="",AK14=0),0,AL14-$W14) -> -8345.4466 | GS14: =IF(AK14=0,"",GR14/$W14) -> -0.018287845 | GT14: =GB14 -> JUN | GU14: =IF($GT14="jan",$GR14/12,0) -> 0 | GV14: =IF(GU14<>0,GU14,IF($GT14="fev",$GR14/12,0)) -> 0 | GW14: =IF(GV14<>0,GV14,IF($GT14="mar",$GR14/12,0)) -> 0 | GX14: =IF(GW14<>0,GW14,IF($GT14="abr",$GR14/12,0)) -> 0 | GY14: =IF(GX14<>0,GX14,IF($GT14="mai",$GR14/12,0)) -> 0 | GZ14: =IF(GY14<>0,GY14,IF($GT14="jun",$GR14/12,0)) -> -695.45388 | HA14: =IF(GZ14<>0,GZ14,IF($GT14="jul",$GR14/12,0)) -> -695.45388 | HB14: =IF(HA14<>0,HA14,IF($GT14="ago",$GR14/12,0)) -> -695.45388 | HC14: =IF(HB14<>0,HB14,IF($GT14="set",$GR14/12,0)) -> -695.45388 | HD14: =IF(HC14<>0,HC14,IF($GT14="out",$GR14/12,0)) -> -695.45388 | HE14: =IF(HD14<>0,HD14,IF($GT14="nov",$GR14/12,0)) -> -695.45388 | HF14: =IF(HE14<>0,HE14,IF($GT14="dez",$GR14/12,0)) -> -695.45388 | HG14: =SUM(GU14:HF14) -> -4868.1772 | HH14: =IF(GT14=0,"",IF(GR14=0,0,GR14-HG14)) -> -3477.2694 | HI14: =IF(HG14=0,"",IF(HG14=FZ14,0,IF(HG14<FZ14,1,2))) -> #REF! | HK14: 1 | HL14: 1 | HM14: =IF($GB14<>"",$GB14,IFERROR(T(INDEX('MATRIZ 2X2'!$J$20:$J$367,MATCH(UPPER(TRIM(SUBSTITUTE(IF(ISNUMBER(VALUE(LEFT(TRIM(J14),6))),MID(TRIM(J14),FIND(" ",TRIM(J14))+1,300),TRIM(J14)),".",""))),'MATRIZ 2X2'!$P$20:$P$367,0))),"")) -> JUN | HN14: =IFERROR(INDEX('MATRIZ 2X2'!$G$20:$G$367,MATCH(UPPER(TRIM(SUBSTITUTE(IF(ISNUMBER(VALUE(LEFT(TRIM(J14),6))),MID(TRIM(J14),FIND(" ",TRIM(J14))+1,300),TRIM(J14)),".",""))),'MATRIZ 2X2'!$P$20:$P$367,0)),"")
A15: =TRIM(E15) -> 212235 | B15: LABORATORIO | C15: PRÉ ANALITICO | D15: TUBO | E15: 212235 | F15: VAC GEL SST 5ML 360060 TB 13X100MM | G15: SP | H15: 3069 | I15: NDI-CD LAPA | J15: GREINER BIO-ONE BRASIL PRO MED HOSP | K15: 578400 | L15: =M15*K15 -> 414050.55 | M15: 0.71585503 | N15: 0.64 | O15: =N15*K15 -> 370176 | P15: BECTON DICKINSON INDUSTRIAS CIRURGI | Q15: 0.62803448 | R15: =IF($Q15="",0,$Q15*$K15) -> 363255.14 | S15: =R15/12 -> 30271.262 | T15: =IF($Q15=0,0,$R15-$L15) -> -50795.406 | U15: =IFERROR(IF(OR(Q15="",Q15=0),"",T15/L15),"") -> -0.12267924 | V15: 0.63755821 | W15: =IF($V15="",0,$V15*$K15) -> 368763.67 | X15: =W15/12 -> 30730.306 | Y15: =IF($V15=0,0,$W15-$L15) -> -45286.882 | Z15: =IFERROR(IF(OR(V15="",V15=0),"",Y15/L15),"") -> -0.10937525 | AA15: 0.12 | AB15: =Q15-Q15*AA15 -> 0.55267034 | AC15: =AB15*K15 -> 319664.53 | AD15: =AC15-R15 -> -43590.617 | AE15: =IF(R15=0,"",AD15/R15) -> -0.12 | AF15: =AC15-W15 -> -49099.141 | AG15: =AF15/W15 -> -0.13314528 | AH15: FINALIZADO | AJ15: =IFERROR(INDEX($AO$1:$FM$1,MATCH($AK15,$AO15:$FM15,0)),"") -> BD COLETA | AK15: =MIN(AO15:FM15) -> 0.64 | AL15: =AK15*K15 -> 370176 | AM15: =IF(OR(AK15="",AK15=0),0,AL15-$W15) -> 1412.3322 | AN15: =IF(AK15=0,"",AM15/$W15) -> 0.0038299115 | AR15: 0.64 | FN15: =$AD15*#REF! -> #REF! | FO15: =$AD15*#REF! -> #REF! | FP15: =$AD15*#REF! -> #REF! | FQ15: =$AD15*#REF! -> #REF! | FR15: =$AD15*#REF! -> #REF! | FS15: =$AD15*#REF! -> #REF! | FT15: =$AD15*#REF! -> #REF! | FU15: =$AD15*#REF! -> #REF! | ... FY15: =$AD15*#REF! -> #REF! | FZ15: =SUM(FN15:FY15) -> #REF! | GA15: =AD15-FZ15 -> #REF! | GB15: JUN | GC15: =IF($GB15="jan",$AM15/12,0) -> 0 | GD15: =IF(GC15<>0,GC15,IF($GB15="fev",$AM15/12,0)) -> 0 | GE15: =IF(GD15<>0,GD15,IF($GB15="mar",$AM15/12,0)) -> 0 | GF15: =IF(GE15<>0,GE15,IF($GB15="abr",$AM15/12,0)) -> 0 | GG15: =IF(GF15<>0,GF15,IF($GB15="mai",$AM15/12,0)) -> 0 | GH15: =IF(GG15<>0,GG15,IF($GB15="jun",$AM15/12,0)) -> 117.69435 | GI15: =IF(GH15<>0,GH15,IF($GB15="jul",$AM15/12,0)) -> 117.69435 | GJ15: =IF(GI15<>0,GI15,IF($GB15="ago",$AM15/12,0)) -> 117.69435 | GK15: =IF(GJ15<>0,GJ15,IF($GB15="set",$AM15/12,0)) -> 117.69435 | GL15: =IF(GK15<>0,GK15,IF($GB15="out",$AM15/12,0)) -> 117.69435 | GM15: =IF(GL15<>0,GL15,IF($GB15="nov",$AM15/12,0)) -> 117.69435 | GN15: =IF(GM15<>0,GM15,IF($GB15="dez",$AM15/12,0)) -> 117.69435 | GO15: =SUM(GC15:GN15) -> 823.86045 | GP15: =IF(GB15="","",IF(AM15=0,0,AM15-GO15)) -> 588.47175 | GQ15: =IF(GO15=0,"",IF(GO15=FZ15,0,IF(GO15<FZ15,1,2))) -> #REF! | GR15: =IF(OR(AK15="",AK15=0),0,AL15-$W15) -> 1412.3322 | GS15: =IF(AK15=0,"",GR15/$W15) -> 0.0038299115 | GT15: =GB15 -> JUN | GU15: =IF($GT15="jan",$GR15/12,0) -> 0 | GV15: =IF(GU15<>0,GU15,IF($GT15="fev",$GR15/12,0)) -> 0 | GW15: =IF(GV15<>0,GV15,IF($GT15="mar",$GR15/12,0)) -> 0 | GX15: =IF(GW15<>0,GW15,IF($GT15="abr",$GR15/12,0)) -> 0 | GY15: =IF(GX15<>0,GX15,IF($GT15="mai",$GR15/12,0)) -> 0 | GZ15: =IF(GY15<>0,GY15,IF($GT15="jun",$GR15/12,0)) -> 117.69435 | HA15: =IF(GZ15<>0,GZ15,IF($GT15="jul",$GR15/12,0)) -> 117.69435 | HB15: =IF(HA15<>0,HA15,IF($GT15="ago",$GR15/12,0)) -> 117.69435 | HC15: =IF(HB15<>0,HB15,IF($GT15="set",$GR15/12,0)) -> 117.69435 | HD15: =IF(HC15<>0,HC15,IF($GT15="out",$GR15/12,0)) -> 117.69435 | HE15: =IF(HD15<>0,HD15,IF($GT15="nov",$GR15/12,0)) -> 117.69435 | HF15: =IF(HE15<>0,HE15,IF($GT15="dez",$GR15/12,0)) -> 117.69435 | HG15: =SUM(GU15:HF15) -> 823.86045 | HH15: =IF(GT15=0,"",IF(GR15=0,0,GR15-HG15)) -> 588.47175 | HI15: =IF(HG15=0,"",IF(HG15=FZ15,0,IF(HG15<FZ15,1,2))) -> #REF! | HK15: 0 | HL15: 0 | HM15: =IF($GB15<>"",$GB15,IFERROR(T(INDEX('MATRIZ 2X2'!$J$20:$J$367,MATCH(UPPER(TRIM(SUBSTITUTE(IF(ISNUMBER(VALUE(LEFT(TRIM(J15),6))),MID(TRIM(J15),FIND(" ",TRIM(J15))+1,300),TRIM(J15)),".",""))),'MATRIZ 2X2'!$P$20:$P$367,0))),"")) -> JUN | HN15: =IFERROR(INDEX('MATRIZ 2X2'!$G$20:$G$367,MATCH(UPPER(TRIM(SUBSTITUTE(IF(ISNUMBER(VALUE(LEFT(TRIM(J15),6))),MID(TRIM(J15),FIND(" ",TRIM(J15))+1,300),TRIM(J15)),".",""))),'MATRIZ 2X2'!$P$20:$P$367,0)),"")
